2025-03-15 11:16:04,252 : INFO : root : Loading config.
2025-03-15 11:16:04,259 : INFO : YamlMultifileConfigLoader : Machine config file #1: config.yaml
2025-03-15 11:16:04,263 : INFO : ConfigProcessor : Loading config from cache: C:\Users\User\AppData\Local\Temp\5682b9bdeb2b9ad8a31c13560e038609.mpf_cache
2025-03-15 11:16:04,500 : INFO : ConfigProcessor : Loading config from cache: C:\Users\User\AppData\Local\Temp\8422c6572f827355f8aade1949d04025.mpf_cache
2025-03-15 11:16:04,503 : INFO : ConfigProcessor : Loading config from cache: C:\Users\User\AppData\Local\Temp\1c0e7e9816717d8e62c4728dfe372999.mpf_cache
2025-03-15 11:16:04,504 : INFO : ConfigProcessor : Loading config from cache: C:\Users\User\AppData\Local\Temp\e3e8065d662ad307fa9574659e7e4e8e.mpf_cache
2025-03-15 11:16:04,505 : INFO : ConfigProcessor : Loading config from cache: C:\Users\User\AppData\Local\Temp\8422c6572f827355f8aade1949d04025.mpf_cache
2025-03-15 11:16:04,507 : INFO : Machine : Mission Pinball Framework Core Engine v0.80.0.dev6
2025-03-15 11:16:04,507 : INFO : Machine : Command line arguments: {'no_load_cache': False, 'create_config_cache': True, 'bcp': False, 'configfile': ['config.yaml'], 'force_assets_load': False, 'platform_integration_test': False, 'jsonlogging': False, 'logfile': 'logs\\2025-03-15-11-16-04-mpf-BERNIE.log', 'pause': False, 'production': False, 'text_ui': False, 'loglevel': 15, 'consoleloglevel': 20, 'force_platform': None, 'syslog_address': None, 'full_logfile_path': 'C:\\Users\\User\\Desktop\\fast_homebrew_godot_v2\\fast_homebrew_godot_v2\\logs\\2025-03-15-11-16-04-mpf-BERNIE.log'}
2025-03-15 11:16:04,507 : INFO : Machine : MPF path: C:\Users\User\AppData\Local\Programs\Python\Python312\Lib\site-packages\mpf
2025-03-15 11:16:04,507 : INFO : Machine : Machine path: C:\Users\User\Desktop\fast_homebrew_godot_v2\fast_homebrew_godot_v2
2025-03-15 11:16:04,507 : INFO : Machine : Platform: win32
2025-03-15 11:16:04,508 : INFO : Machine : Python executable location: C:\Users\User\AppData\Local\Programs\Python\Python312\python.exe
2025-03-15 11:16:04,508 : INFO : Machine : Python version: 3.12.3 (64-bit)
2025-03-15 11:16:04,516 : INFO : Machine : Initializing MPF...
2025-03-15 11:16:04,744 : INFO : FAST : Auto-detecting ports for the following connections: ['net']
2025-03-15 11:16:04,792 : INFO : FAST : Detected NET on port COM5
2025-03-15 11:16:04,904 : INFO : FAST [NET] : Trying to connect to COM5 at 921600bps
2025-03-15 11:16:04,912 : INFO : FAST [NET] : Connected to COM5 at 921600bps
2025-03-15 11:16:04,917 : INFO : FAST [NET] : Connected to FP-CPU-2000 with firmware v02.26
2025-03-15 11:16:04,949 : INFO : EventManager : Event: ======'machine_var_credits_string'====== Args={'value': 'FREE PLAY', 'prev_value': None, 'change': True}
2025-03-15 11:16:05,012 : INFO : EventManager : Event: ======'machine_var_master_volume'====== Args={'value': 0.5, 'prev_value': None, 'change': True}
2025-03-15 11:16:05,013 : INFO : EventManager : Event: ======'machine_var_mpf_version'====== Args={'value': 'Mission Pinball Framework v0.80.0.dev6', 'prev_value': None, 'change': True}
2025-03-15 11:16:05,013 : INFO : EventManager : Event: ======'machine_var_mpf_extended_version'====== Args={'value': 'Mission Pinball Framework v0.80.0.dev6, Config version:6, Show version: 6, BCP version:1.1', 'prev_value': None, 'change': True}
2025-03-15 11:16:05,014 : INFO : EventManager : Event: ======'machine_var_python_version'====== Args={'value': '3.12.3', 'prev_value': None, 'change': True}
2025-03-15 11:16:05,170 : INFO : EventManager : Event: ======'machine_var_platform'====== Args={'value': 'Windows-11-10.0.22631-SP0', 'prev_value': None, 'change': True}
2025-03-15 11:16:05,170 : INFO : EventManager : Event: ======'machine_var_platform_system'====== Args={'value': 'Windows', 'prev_value': None, 'change': True}
2025-03-15 11:16:05,170 : INFO : EventManager : Event: ======'machine_var_platform_release'====== Args={'value': '11', 'prev_value': None, 'change': True}
2025-03-15 11:16:05,170 : INFO : EventManager : Event: ======'machine_var_platform_version'====== Args={'value': '10.0.22631', 'prev_value': None, 'change': True}
2025-03-15 11:16:05,170 : INFO : EventManager : Event: ======'machine_var_platform_machine'====== Args={'value': 'AMD64', 'prev_value': None, 'change': True}
2025-03-15 11:16:05,170 : INFO : EventManager : Event: ======'machine_var_log_file_path'====== Args={'value': 'C:\\Users\\User\\Desktop\\fast_homebrew_godot_v2\\fast_homebrew_godot_v2\\logs\\2025-03-15-11-16-04-mpf-BERNIE.log', 'prev_value': None, 'change': True}
2025-03-15 11:16:05,171 : INFO : EventManager : Event: ======'init_phase_1'====== Args={}
2025-03-15 11:16:05,234 : ERROR : asyncio : Task exception was never retrieved
future: <Task finished name='Task-32' coro=<SystemWideDevice.device_added_system_wide() done, defined at C:\Users\User\AppData\Local\Programs\Python\Python312\Lib\site-packages\mpf\core\system_wide_device.py:15> exception=ConfigFileError('Failed to configure switch s_trough_ball_5 in platform. See error above')>
Traceback (most recent call last):
  File "C:\Users\User\AppData\Local\Programs\Python\Python312\Lib\site-packages\mpf\platforms\fast\fast.py", line 447, in _parse_switch_number
    board = self.io_boards_by_name[board_str]
            ~~~~~~~~~~~~~~~~~~~~~~^^^^^^^^^^^
KeyError: '3208'

During handling of the above exception, another exception occurred:

Traceback (most recent call last):
  File "C:\Users\User\AppData\Local\Programs\Python\Python312\Lib\site-packages\mpf\devices\switch.py", line 149, in _initialize
    self.hw_switch = self.platform.configure_switch(
                     ^^^^^^^^^^^^^^^^^^^^^^^^^^^^^^^
  File "C:\Users\User\AppData\Local\Programs\Python\Python312\Lib\site-packages\mpf\platforms\fast\fast.py", line 505, in configure_switch
    number = self._parse_switch_number(number)
             ^^^^^^^^^^^^^^^^^^^^^^^^^^^^^^^^^
  File "C:\Users\User\AppData\Local\Programs\Python\Python312\Lib\site-packages\mpf\platforms\fast\fast.py", line 449, in _parse_switch_number
    raise AssertionError(f"Board {board_str} does not exist for switch {number}")
AssertionError: Board 3208 does not exist for switch 3208-4

The above exception was the direct cause of the following exception:

Traceback (most recent call last):
  File "C:\Users\User\AppData\Local\Programs\Python\Python312\Lib\site-packages\mpf\core\system_wide_device.py", line 17, in device_added_system_wide
    await self._initialize()
  File "C:\Users\User\AppData\Local\Programs\Python\Python312\Lib\site-packages\mpf\devices\switch.py", line 152, in _initialize
    raise ConfigFileError("Failed to configure switch {} in platform. See error above".format(self.name), 2,
mpf.exceptions.config_file_error.ConfigFileError: Config File Error in switch: Failed to configure switch s_trough_ball_5 in platform. See error above Error Code: CFE-switch-2 (https://missionpinball.org/logs)
2025-03-15 11:16:05,238 : ERROR : asyncio : Task exception was never retrieved
future: <Task finished name='Task-44' coro=<SystemWideDevice.device_added_system_wide() done, defined at C:\Users\User\AppData\Local\Programs\Python\Python312\Lib\site-packages\mpf\core\system_wide_device.py:15> exception=ConfigFileError('Failed to configure switch s_slingshot_2 in platform. See error above')>
Traceback (most recent call last):
  File "C:\Users\User\AppData\Local\Programs\Python\Python312\Lib\site-packages\mpf\platforms\fast\fast.py", line 433, in _parse_switch_number
    board_str, switch_str = number.split("-")
    ^^^^^^^^^^^^^^^^^^^^^
ValueError: not enough values to unpack (expected 2, got 1)

The above exception was the direct cause of the following exception:

Traceback (most recent call last):
  File "C:\Users\User\AppData\Local\Programs\Python\Python312\Lib\site-packages\mpf\devices\switch.py", line 149, in _initialize
    self.hw_switch = self.platform.configure_switch(
                     ^^^^^^^^^^^^^^^^^^^^^^^^^^^^^^^
  File "C:\Users\User\AppData\Local\Programs\Python\Python312\Lib\site-packages\mpf\platforms\fast\fast.py", line 505, in configure_switch
    number = self._parse_switch_number(number)
             ^^^^^^^^^^^^^^^^^^^^^^^^^^^^^^^^^
  File "C:\Users\User\AppData\Local\Programs\Python\Python312\Lib\site-packages\mpf\platforms\fast\fast.py", line 441, in _parse_switch_number
    raise AssertionError(f"Switch {int(index, 16)} does not exist. Only "
AssertionError: Switch 16 does not exist. Only 0 switches found. Switch number: 16

The above exception was the direct cause of the following exception:

Traceback (most recent call last):
  File "C:\Users\User\AppData\Local\Programs\Python\Python312\Lib\site-packages\mpf\core\system_wide_device.py", line 17, in device_added_system_wide
    await self._initialize()
  File "C:\Users\User\AppData\Local\Programs\Python\Python312\Lib\site-packages\mpf\devices\switch.py", line 152, in _initialize
    raise ConfigFileError("Failed to configure switch {} in platform. See error above".format(self.name), 2,
mpf.exceptions.config_file_error.ConfigFileError: Config File Error in switch: Failed to configure switch s_slingshot_2 in platform. See error above Error Code: CFE-switch-2 (https://missionpinball.org/logs)
2025-03-15 11:16:05,241 : ERROR : asyncio : Task exception was never retrieved
future: <Task finished name='Task-33' coro=<SystemWideDevice.device_added_system_wide() done, defined at C:\Users\User\AppData\Local\Programs\Python\Python312\Lib\site-packages\mpf\core\system_wide_device.py:15> exception=ConfigFileError('Failed to configure switch s_trough_ball_6 in platform. See error above')>
Traceback (most recent call last):
  File "C:\Users\User\AppData\Local\Programs\Python\Python312\Lib\site-packages\mpf\platforms\fast\fast.py", line 447, in _parse_switch_number
    board = self.io_boards_by_name[board_str]
            ~~~~~~~~~~~~~~~~~~~~~~^^^^^^^^^^^
KeyError: '3208'

During handling of the above exception, another exception occurred:

Traceback (most recent call last):
  File "C:\Users\User\AppData\Local\Programs\Python\Python312\Lib\site-packages\mpf\devices\switch.py", line 149, in _initialize
    self.hw_switch = self.platform.configure_switch(
                     ^^^^^^^^^^^^^^^^^^^^^^^^^^^^^^^
  File "C:\Users\User\AppData\Local\Programs\Python\Python312\Lib\site-packages\mpf\platforms\fast\fast.py", line 505, in configure_switch
    number = self._parse_switch_number(number)
             ^^^^^^^^^^^^^^^^^^^^^^^^^^^^^^^^^
  File "C:\Users\User\AppData\Local\Programs\Python\Python312\Lib\site-packages\mpf\platforms\fast\fast.py", line 449, in _parse_switch_number
    raise AssertionError(f"Board {board_str} does not exist for switch {number}")
AssertionError: Board 3208 does not exist for switch 3208-5

The above exception was the direct cause of the following exception:

Traceback (most recent call last):
  File "C:\Users\User\AppData\Local\Programs\Python\Python312\Lib\site-packages\mpf\core\system_wide_device.py", line 17, in device_added_system_wide
    await self._initialize()
  File "C:\Users\User\AppData\Local\Programs\Python\Python312\Lib\site-packages\mpf\devices\switch.py", line 152, in _initialize
    raise ConfigFileError("Failed to configure switch {} in platform. See error above".format(self.name), 2,
mpf.exceptions.config_file_error.ConfigFileError: Config File Error in switch: Failed to configure switch s_trough_ball_6 in platform. See error above Error Code: CFE-switch-2 (https://missionpinball.org/logs)
2025-03-15 11:16:05,243 : ERROR : asyncio : Task exception was never retrieved
future: <Task finished name='Task-45' coro=<SystemWideDevice.device_added_system_wide() done, defined at C:\Users\User\AppData\Local\Programs\Python\Python312\Lib\site-packages\mpf\core\system_wide_device.py:15> exception=ConfigFileError('Failed to configure switch s_start in platform. See error above')>
Traceback (most recent call last):
  File "C:\Users\User\AppData\Local\Programs\Python\Python312\Lib\site-packages\mpf\platforms\fast\fast.py", line 433, in _parse_switch_number
    board_str, switch_str = number.split("-")
    ^^^^^^^^^^^^^^^^^^^^^
ValueError: not enough values to unpack (expected 2, got 1)

The above exception was the direct cause of the following exception:

Traceback (most recent call last):
  File "C:\Users\User\AppData\Local\Programs\Python\Python312\Lib\site-packages\mpf\devices\switch.py", line 149, in _initialize
    self.hw_switch = self.platform.configure_switch(
                     ^^^^^^^^^^^^^^^^^^^^^^^^^^^^^^^
  File "C:\Users\User\AppData\Local\Programs\Python\Python312\Lib\site-packages\mpf\platforms\fast\fast.py", line 505, in configure_switch
    number = self._parse_switch_number(number)
             ^^^^^^^^^^^^^^^^^^^^^^^^^^^^^^^^^
  File "C:\Users\User\AppData\Local\Programs\Python\Python312\Lib\site-packages\mpf\platforms\fast\fast.py", line 441, in _parse_switch_number
    raise AssertionError(f"Switch {int(index, 16)} does not exist. Only "
AssertionError: Switch 29 does not exist. Only 0 switches found. Switch number: 29

The above exception was the direct cause of the following exception:

Traceback (most recent call last):
  File "C:\Users\User\AppData\Local\Programs\Python\Python312\Lib\site-packages\mpf\core\system_wide_device.py", line 17, in device_added_system_wide
    await self._initialize()
  File "C:\Users\User\AppData\Local\Programs\Python\Python312\Lib\site-packages\mpf\devices\switch.py", line 152, in _initialize
    raise ConfigFileError("Failed to configure switch {} in platform. See error above".format(self.name), 2,
mpf.exceptions.config_file_error.ConfigFileError: Config File Error in switch: Failed to configure switch s_start in platform. See error above Error Code: CFE-switch-2 (https://missionpinball.org/logs)
2025-03-15 11:16:05,245 : ERROR : asyncio : Task exception was never retrieved
future: <Task finished name='Task-14' coro=<SystemWideDevice.device_added_system_wide() done, defined at C:\Users\User\AppData\Local\Programs\Python\Python312\Lib\site-packages\mpf\core\system_wide_device.py:15> exception=AssertionError('Failed to configure driver c_trough_eject_coil in platform. See error above')>
Traceback (most recent call last):
  File "C:\Users\User\AppData\Local\Programs\Python\Python312\Lib\site-packages\mpf\platforms\fast\fast.py", line 338, in _parse_driver_number
    board = self.io_boards_by_name[board_str]
            ~~~~~~~~~~~~~~~~~~~~~~^^^^^^^^^^^
KeyError: '3208'

During handling of the above exception, another exception occurred:

Traceback (most recent call last):
  File "C:\Users\User\AppData\Local\Programs\Python\Python312\Lib\site-packages\mpf\devices\driver.py", line 118, in _initialize
    self.hw_driver = self.platform.configure_driver(config, self.config['number'], platform_settings)
                     ^^^^^^^^^^^^^^^^^^^^^^^^^^^^^^^^^^^^^^^^^^^^^^^^^^^^^^^^^^^^^^^^^^^^^^^^^^^^^^^^
  File "C:\Users\User\AppData\Local\Programs\Python\Python312\Lib\site-packages\mpf\platforms\fast\fast.py", line 387, in configure_driver
    index = self._parse_driver_number(number)
            ^^^^^^^^^^^^^^^^^^^^^^^^^^^^^^^^^
  File "C:\Users\User\AppData\Local\Programs\Python\Python312\Lib\site-packages\mpf\platforms\fast\fast.py", line 340, in _parse_driver_number
    raise AssertionError(f"I/O Board {board_str} does not exist for driver {number}")
AssertionError: I/O Board 3208 does not exist for driver 3208-0

The above exception was the direct cause of the following exception:

Traceback (most recent call last):
  File "C:\Users\User\AppData\Local\Programs\Python\Python312\Lib\site-packages\mpf\core\system_wide_device.py", line 17, in device_added_system_wide
    await self._initialize()
  File "C:\Users\User\AppData\Local\Programs\Python\Python312\Lib\site-packages\mpf\devices\driver.py", line 120, in _initialize
    raise AssertionError("Failed to configure driver {} in platform. See error above".format(self.name)) from e
AssertionError: Failed to configure driver c_trough_eject_coil in platform. See error above
2025-03-15 11:16:05,248 : ERROR : asyncio : Task exception was never retrieved
future: <Task finished name='Task-34' coro=<SystemWideDevice.device_added_system_wide() done, defined at C:\Users\User\AppData\Local\Programs\Python\Python312\Lib\site-packages\mpf\core\system_wide_device.py:15> exception=ConfigFileError('Failed to configure switch s_flipper_left in platform. See error above')>
Traceback (most recent call last):
  File "C:\Users\User\AppData\Local\Programs\Python\Python312\Lib\site-packages\mpf\platforms\fast\fast.py", line 433, in _parse_switch_number
    board_str, switch_str = number.split("-")
    ^^^^^^^^^^^^^^^^^^^^^
ValueError: not enough values to unpack (expected 2, got 1)

The above exception was the direct cause of the following exception:

Traceback (most recent call last):
  File "C:\Users\User\AppData\Local\Programs\Python\Python312\Lib\site-packages\mpf\devices\switch.py", line 149, in _initialize
    self.hw_switch = self.platform.configure_switch(
                     ^^^^^^^^^^^^^^^^^^^^^^^^^^^^^^^
  File "C:\Users\User\AppData\Local\Programs\Python\Python312\Lib\site-packages\mpf\platforms\fast\fast.py", line 505, in configure_switch
    number = self._parse_switch_number(number)
             ^^^^^^^^^^^^^^^^^^^^^^^^^^^^^^^^^
  File "C:\Users\User\AppData\Local\Programs\Python\Python312\Lib\site-packages\mpf\platforms\fast\fast.py", line 441, in _parse_switch_number
    raise AssertionError(f"Switch {int(index, 16)} does not exist. Only "
AssertionError: Switch 30 does not exist. Only 0 switches found. Switch number: 30

The above exception was the direct cause of the following exception:

Traceback (most recent call last):
  File "C:\Users\User\AppData\Local\Programs\Python\Python312\Lib\site-packages\mpf\core\system_wide_device.py", line 17, in device_added_system_wide
    await self._initialize()
  File "C:\Users\User\AppData\Local\Programs\Python\Python312\Lib\site-packages\mpf\devices\switch.py", line 152, in _initialize
    raise ConfigFileError("Failed to configure switch {} in platform. See error above".format(self.name), 2,
mpf.exceptions.config_file_error.ConfigFileError: Config File Error in switch: Failed to configure switch s_flipper_left in platform. See error above Error Code: CFE-switch-2 (https://missionpinball.org/logs)
2025-03-15 11:16:05,250 : ERROR : asyncio : Task exception was never retrieved
future: <Task finished name='Task-35' coro=<SystemWideDevice.device_added_system_wide() done, defined at C:\Users\User\AppData\Local\Programs\Python\Python312\Lib\site-packages\mpf\core\system_wide_device.py:15> exception=ConfigFileError('Failed to configure switch s_flipper_right in platform. See error above')>
Traceback (most recent call last):
  File "C:\Users\User\AppData\Local\Programs\Python\Python312\Lib\site-packages\mpf\platforms\fast\fast.py", line 433, in _parse_switch_number
    board_str, switch_str = number.split("-")
    ^^^^^^^^^^^^^^^^^^^^^
ValueError: not enough values to unpack (expected 2, got 1)

The above exception was the direct cause of the following exception:

Traceback (most recent call last):
  File "C:\Users\User\AppData\Local\Programs\Python\Python312\Lib\site-packages\mpf\devices\switch.py", line 149, in _initialize
    self.hw_switch = self.platform.configure_switch(
                     ^^^^^^^^^^^^^^^^^^^^^^^^^^^^^^^
  File "C:\Users\User\AppData\Local\Programs\Python\Python312\Lib\site-packages\mpf\platforms\fast\fast.py", line 505, in configure_switch
    number = self._parse_switch_number(number)
             ^^^^^^^^^^^^^^^^^^^^^^^^^^^^^^^^^
  File "C:\Users\User\AppData\Local\Programs\Python\Python312\Lib\site-packages\mpf\platforms\fast\fast.py", line 441, in _parse_switch_number
    raise AssertionError(f"Switch {int(index, 16)} does not exist. Only "
AssertionError: Switch 31 does not exist. Only 0 switches found. Switch number: 31

The above exception was the direct cause of the following exception:

Traceback (most recent call last):
  File "C:\Users\User\AppData\Local\Programs\Python\Python312\Lib\site-packages\mpf\core\system_wide_device.py", line 17, in device_added_system_wide
    await self._initialize()
  File "C:\Users\User\AppData\Local\Programs\Python\Python312\Lib\site-packages\mpf\devices\switch.py", line 152, in _initialize
    raise ConfigFileError("Failed to configure switch {} in platform. See error above".format(self.name), 2,
mpf.exceptions.config_file_error.ConfigFileError: Config File Error in switch: Failed to configure switch s_flipper_right in platform. See error above Error Code: CFE-switch-2 (https://missionpinball.org/logs)
2025-03-15 11:16:05,252 : ERROR : asyncio : Task exception was never retrieved
future: <Task finished name='Task-26' coro=<SystemWideDevice.device_added_system_wide() done, defined at C:\Users\User\AppData\Local\Programs\Python\Python312\Lib\site-packages\mpf\core\system_wide_device.py:15> exception=ConfigFileError('Failed to configure switch s_plunger in platform. See error above')>
Traceback (most recent call last):
  File "C:\Users\User\AppData\Local\Programs\Python\Python312\Lib\site-packages\mpf\platforms\fast\fast.py", line 433, in _parse_switch_number
    board_str, switch_str = number.split("-")
    ^^^^^^^^^^^^^^^^^^^^^
ValueError: not enough values to unpack (expected 2, got 1)

The above exception was the direct cause of the following exception:

Traceback (most recent call last):
  File "C:\Users\User\AppData\Local\Programs\Python\Python312\Lib\site-packages\mpf\devices\switch.py", line 149, in _initialize
    self.hw_switch = self.platform.configure_switch(
                     ^^^^^^^^^^^^^^^^^^^^^^^^^^^^^^^
  File "C:\Users\User\AppData\Local\Programs\Python\Python312\Lib\site-packages\mpf\platforms\fast\fast.py", line 505, in configure_switch
    number = self._parse_switch_number(number)
             ^^^^^^^^^^^^^^^^^^^^^^^^^^^^^^^^^
  File "C:\Users\User\AppData\Local\Programs\Python\Python312\Lib\site-packages\mpf\platforms\fast\fast.py", line 441, in _parse_switch_number
    raise AssertionError(f"Switch {int(index, 16)} does not exist. Only "
AssertionError: Switch 27 does not exist. Only 0 switches found. Switch number: 27

The above exception was the direct cause of the following exception:

Traceback (most recent call last):
  File "C:\Users\User\AppData\Local\Programs\Python\Python312\Lib\site-packages\mpf\core\system_wide_device.py", line 17, in device_added_system_wide
    await self._initialize()
  File "C:\Users\User\AppData\Local\Programs\Python\Python312\Lib\site-packages\mpf\devices\switch.py", line 152, in _initialize
    raise ConfigFileError("Failed to configure switch {} in platform. See error above".format(self.name), 2,
mpf.exceptions.config_file_error.ConfigFileError: Config File Error in switch: Failed to configure switch s_plunger in platform. See error above Error Code: CFE-switch-2 (https://missionpinball.org/logs)
2025-03-15 11:16:05,254 : ERROR : asyncio : Task exception was never retrieved
future: <Task finished name='Task-36' coro=<SystemWideDevice.device_added_system_wide() done, defined at C:\Users\User\AppData\Local\Programs\Python\Python312\Lib\site-packages\mpf\core\system_wide_device.py:15> exception=ConfigFileError('Failed to configure switch s_flipper_left_upper_eos in platform. See error above')>
Traceback (most recent call last):
  File "C:\Users\User\AppData\Local\Programs\Python\Python312\Lib\site-packages\mpf\platforms\fast\fast.py", line 433, in _parse_switch_number
    board_str, switch_str = number.split("-")
    ^^^^^^^^^^^^^^^^^^^^^
ValueError: not enough values to unpack (expected 2, got 1)

The above exception was the direct cause of the following exception:

Traceback (most recent call last):
  File "C:\Users\User\AppData\Local\Programs\Python\Python312\Lib\site-packages\mpf\devices\switch.py", line 149, in _initialize
    self.hw_switch = self.platform.configure_switch(
                     ^^^^^^^^^^^^^^^^^^^^^^^^^^^^^^^
  File "C:\Users\User\AppData\Local\Programs\Python\Python312\Lib\site-packages\mpf\platforms\fast\fast.py", line 505, in configure_switch
    number = self._parse_switch_number(number)
             ^^^^^^^^^^^^^^^^^^^^^^^^^^^^^^^^^
  File "C:\Users\User\AppData\Local\Programs\Python\Python312\Lib\site-packages\mpf\platforms\fast\fast.py", line 441, in _parse_switch_number
    raise AssertionError(f"Switch {int(index, 16)} does not exist. Only "
AssertionError: Switch 20 does not exist. Only 0 switches found. Switch number: 20

The above exception was the direct cause of the following exception:

Traceback (most recent call last):
  File "C:\Users\User\AppData\Local\Programs\Python\Python312\Lib\site-packages\mpf\core\system_wide_device.py", line 17, in device_added_system_wide
    await self._initialize()
  File "C:\Users\User\AppData\Local\Programs\Python\Python312\Lib\site-packages\mpf\devices\switch.py", line 152, in _initialize
    raise ConfigFileError("Failed to configure switch {} in platform. See error above".format(self.name), 2,
mpf.exceptions.config_file_error.ConfigFileError: Config File Error in switch: Failed to configure switch s_flipper_left_upper_eos in platform. See error above Error Code: CFE-switch-2 (https://missionpinball.org/logs)
2025-03-15 11:16:05,255 : ERROR : asyncio : Task exception was never retrieved
future: <Task finished name='Task-27' coro=<SystemWideDevice.device_added_system_wide() done, defined at C:\Users\User\AppData\Local\Programs\Python\Python312\Lib\site-packages\mpf\core\system_wide_device.py:15> exception=ConfigFileError('Failed to configure switch s_trough_ball_jam in platform. See error above')>
Traceback (most recent call last):
  File "C:\Users\User\AppData\Local\Programs\Python\Python312\Lib\site-packages\mpf\platforms\fast\fast.py", line 447, in _parse_switch_number
    board = self.io_boards_by_name[board_str]
            ~~~~~~~~~~~~~~~~~~~~~~^^^^^^^^^^^
KeyError: '3208'

During handling of the above exception, another exception occurred:

Traceback (most recent call last):
  File "C:\Users\User\AppData\Local\Programs\Python\Python312\Lib\site-packages\mpf\devices\switch.py", line 149, in _initialize
    self.hw_switch = self.platform.configure_switch(
                     ^^^^^^^^^^^^^^^^^^^^^^^^^^^^^^^
  File "C:\Users\User\AppData\Local\Programs\Python\Python312\Lib\site-packages\mpf\platforms\fast\fast.py", line 505, in configure_switch
    number = self._parse_switch_number(number)
             ^^^^^^^^^^^^^^^^^^^^^^^^^^^^^^^^^
  File "C:\Users\User\AppData\Local\Programs\Python\Python312\Lib\site-packages\mpf\platforms\fast\fast.py", line 449, in _parse_switch_number
    raise AssertionError(f"Board {board_str} does not exist for switch {number}")
AssertionError: Board 3208 does not exist for switch 3208-6

The above exception was the direct cause of the following exception:

Traceback (most recent call last):
  File "C:\Users\User\AppData\Local\Programs\Python\Python312\Lib\site-packages\mpf\core\system_wide_device.py", line 17, in device_added_system_wide
    await self._initialize()
  File "C:\Users\User\AppData\Local\Programs\Python\Python312\Lib\site-packages\mpf\devices\switch.py", line 152, in _initialize
    raise ConfigFileError("Failed to configure switch {} in platform. See error above".format(self.name), 2,
mpf.exceptions.config_file_error.ConfigFileError: Config File Error in switch: Failed to configure switch s_trough_ball_jam in platform. See error above Error Code: CFE-switch-2 (https://missionpinball.org/logs)
2025-03-15 11:16:05,257 : ERROR : asyncio : Task exception was never retrieved
future: <Task finished name='Task-37' coro=<SystemWideDevice.device_added_system_wide() done, defined at C:\Users\User\AppData\Local\Programs\Python\Python312\Lib\site-packages\mpf\core\system_wide_device.py:15> exception=ConfigFileError('Failed to configure switch s_flipper_left_lower_eos in platform. See error above')>
Traceback (most recent call last):
  File "C:\Users\User\AppData\Local\Programs\Python\Python312\Lib\site-packages\mpf\platforms\fast\fast.py", line 433, in _parse_switch_number
    board_str, switch_str = number.split("-")
    ^^^^^^^^^^^^^^^^^^^^^
ValueError: not enough values to unpack (expected 2, got 1)

The above exception was the direct cause of the following exception:

Traceback (most recent call last):
  File "C:\Users\User\AppData\Local\Programs\Python\Python312\Lib\site-packages\mpf\devices\switch.py", line 149, in _initialize
    self.hw_switch = self.platform.configure_switch(
                     ^^^^^^^^^^^^^^^^^^^^^^^^^^^^^^^
  File "C:\Users\User\AppData\Local\Programs\Python\Python312\Lib\site-packages\mpf\platforms\fast\fast.py", line 505, in configure_switch
    number = self._parse_switch_number(number)
             ^^^^^^^^^^^^^^^^^^^^^^^^^^^^^^^^^
  File "C:\Users\User\AppData\Local\Programs\Python\Python312\Lib\site-packages\mpf\platforms\fast\fast.py", line 441, in _parse_switch_number
    raise AssertionError(f"Switch {int(index, 16)} does not exist. Only "
AssertionError: Switch 19 does not exist. Only 0 switches found. Switch number: 19

The above exception was the direct cause of the following exception:

Traceback (most recent call last):
  File "C:\Users\User\AppData\Local\Programs\Python\Python312\Lib\site-packages\mpf\core\system_wide_device.py", line 17, in device_added_system_wide
    await self._initialize()
  File "C:\Users\User\AppData\Local\Programs\Python\Python312\Lib\site-packages\mpf\devices\switch.py", line 152, in _initialize
    raise ConfigFileError("Failed to configure switch {} in platform. See error above".format(self.name), 2,
mpf.exceptions.config_file_error.ConfigFileError: Config File Error in switch: Failed to configure switch s_flipper_left_lower_eos in platform. See error above Error Code: CFE-switch-2 (https://missionpinball.org/logs)
2025-03-15 11:16:05,258 : ERROR : asyncio : Task exception was never retrieved
future: <Task finished name='Task-28' coro=<SystemWideDevice.device_added_system_wide() done, defined at C:\Users\User\AppData\Local\Programs\Python\Python312\Lib\site-packages\mpf\core\system_wide_device.py:15> exception=ConfigFileError('Failed to configure switch s_trough_ball_1 in platform. See error above')>
Traceback (most recent call last):
  File "C:\Users\User\AppData\Local\Programs\Python\Python312\Lib\site-packages\mpf\platforms\fast\fast.py", line 433, in _parse_switch_number
    board_str, switch_str = number.split("-")
    ^^^^^^^^^^^^^^^^^^^^^
ValueError: not enough values to unpack (expected 2, got 1)

The above exception was the direct cause of the following exception:

Traceback (most recent call last):
  File "C:\Users\User\AppData\Local\Programs\Python\Python312\Lib\site-packages\mpf\devices\switch.py", line 149, in _initialize
    self.hw_switch = self.platform.configure_switch(
                     ^^^^^^^^^^^^^^^^^^^^^^^^^^^^^^^
  File "C:\Users\User\AppData\Local\Programs\Python\Python312\Lib\site-packages\mpf\platforms\fast\fast.py", line 505, in configure_switch
    number = self._parse_switch_number(number)
             ^^^^^^^^^^^^^^^^^^^^^^^^^^^^^^^^^
  File "C:\Users\User\AppData\Local\Programs\Python\Python312\Lib\site-packages\mpf\platforms\fast\fast.py", line 441, in _parse_switch_number
    raise AssertionError(f"Switch {int(index, 16)} does not exist. Only "
AssertionError: Switch 28 does not exist. Only 0 switches found. Switch number: 28

The above exception was the direct cause of the following exception:

Traceback (most recent call last):
  File "C:\Users\User\AppData\Local\Programs\Python\Python312\Lib\site-packages\mpf\core\system_wide_device.py", line 17, in device_added_system_wide
    await self._initialize()
  File "C:\Users\User\AppData\Local\Programs\Python\Python312\Lib\site-packages\mpf\devices\switch.py", line 152, in _initialize
    raise ConfigFileError("Failed to configure switch {} in platform. See error above".format(self.name), 2,
mpf.exceptions.config_file_error.ConfigFileError: Config File Error in switch: Failed to configure switch s_trough_ball_1 in platform. See error above Error Code: CFE-switch-2 (https://missionpinball.org/logs)
2025-03-15 11:16:05,270 : ERROR : asyncio : Task exception was never retrieved
future: <Task finished name='Task-38' coro=<SystemWideDevice.device_added_system_wide() done, defined at C:\Users\User\AppData\Local\Programs\Python\Python312\Lib\site-packages\mpf\core\system_wide_device.py:15> exception=ConfigFileError('Failed to configure switch s_flipper_right_eos in platform. See error above')>
Traceback (most recent call last):
  File "C:\Users\User\AppData\Local\Programs\Python\Python312\Lib\site-packages\mpf\platforms\fast\fast.py", line 433, in _parse_switch_number
    board_str, switch_str = number.split("-")
    ^^^^^^^^^^^^^^^^^^^^^
ValueError: not enough values to unpack (expected 2, got 1)

The above exception was the direct cause of the following exception:

Traceback (most recent call last):
  File "C:\Users\User\AppData\Local\Programs\Python\Python312\Lib\site-packages\mpf\devices\switch.py", line 149, in _initialize
    self.hw_switch = self.platform.configure_switch(
                     ^^^^^^^^^^^^^^^^^^^^^^^^^^^^^^^
  File "C:\Users\User\AppData\Local\Programs\Python\Python312\Lib\site-packages\mpf\platforms\fast\fast.py", line 505, in configure_switch
    number = self._parse_switch_number(number)
             ^^^^^^^^^^^^^^^^^^^^^^^^^^^^^^^^^
  File "C:\Users\User\AppData\Local\Programs\Python\Python312\Lib\site-packages\mpf\platforms\fast\fast.py", line 441, in _parse_switch_number
    raise AssertionError(f"Switch {int(index, 16)} does not exist. Only "
AssertionError: Switch 18 does not exist. Only 0 switches found. Switch number: 18

The above exception was the direct cause of the following exception:

Traceback (most recent call last):
  File "C:\Users\User\AppData\Local\Programs\Python\Python312\Lib\site-packages\mpf\core\system_wide_device.py", line 17, in device_added_system_wide
    await self._initialize()
  File "C:\Users\User\AppData\Local\Programs\Python\Python312\Lib\site-packages\mpf\devices\switch.py", line 152, in _initialize
    raise ConfigFileError("Failed to configure switch {} in platform. See error above".format(self.name), 2,
mpf.exceptions.config_file_error.ConfigFileError: Config File Error in switch: Failed to configure switch s_flipper_right_eos in platform. See error above Error Code: CFE-switch-2 (https://missionpinball.org/logs)
2025-03-15 11:16:05,273 : ERROR : asyncio : Task exception was never retrieved
future: <Task finished name='Task-29' coro=<SystemWideDevice.device_added_system_wide() done, defined at C:\Users\User\AppData\Local\Programs\Python\Python312\Lib\site-packages\mpf\core\system_wide_device.py:15> exception=ConfigFileError('Failed to configure switch s_trough_ball_2 in platform. See error above')>
Traceback (most recent call last):
  File "C:\Users\User\AppData\Local\Programs\Python\Python312\Lib\site-packages\mpf\platforms\fast\fast.py", line 447, in _parse_switch_number
    board = self.io_boards_by_name[board_str]
            ~~~~~~~~~~~~~~~~~~~~~~^^^^^^^^^^^
KeyError: '3208'

During handling of the above exception, another exception occurred:

Traceback (most recent call last):
  File "C:\Users\User\AppData\Local\Programs\Python\Python312\Lib\site-packages\mpf\devices\switch.py", line 149, in _initialize
    self.hw_switch = self.platform.configure_switch(
                     ^^^^^^^^^^^^^^^^^^^^^^^^^^^^^^^
  File "C:\Users\User\AppData\Local\Programs\Python\Python312\Lib\site-packages\mpf\platforms\fast\fast.py", line 505, in configure_switch
    number = self._parse_switch_number(number)
             ^^^^^^^^^^^^^^^^^^^^^^^^^^^^^^^^^
  File "C:\Users\User\AppData\Local\Programs\Python\Python312\Lib\site-packages\mpf\platforms\fast\fast.py", line 449, in _parse_switch_number
    raise AssertionError(f"Board {board_str} does not exist for switch {number}")
AssertionError: Board 3208 does not exist for switch 3208-1

The above exception was the direct cause of the following exception:

Traceback (most recent call last):
  File "C:\Users\User\AppData\Local\Programs\Python\Python312\Lib\site-packages\mpf\core\system_wide_device.py", line 17, in device_added_system_wide
    await self._initialize()
  File "C:\Users\User\AppData\Local\Programs\Python\Python312\Lib\site-packages\mpf\devices\switch.py", line 152, in _initialize
    raise ConfigFileError("Failed to configure switch {} in platform. See error above".format(self.name), 2,
mpf.exceptions.config_file_error.ConfigFileError: Config File Error in switch: Failed to configure switch s_trough_ball_2 in platform. See error above Error Code: CFE-switch-2 (https://missionpinball.org/logs)
2025-03-15 11:16:05,275 : ERROR : asyncio : Task exception was never retrieved
future: <Task finished name='Task-40' coro=<SystemWideDevice.device_added_system_wide() done, defined at C:\Users\User\AppData\Local\Programs\Python\Python312\Lib\site-packages\mpf\core\system_wide_device.py:15> exception=ConfigFileError('Failed to configure switch s_pop_bumper_cc_2 in platform. See error above')>
Traceback (most recent call last):
  File "C:\Users\User\AppData\Local\Programs\Python\Python312\Lib\site-packages\mpf\platforms\fast\fast.py", line 433, in _parse_switch_number
    board_str, switch_str = number.split("-")
    ^^^^^^^^^^^^^^^^^^^^^
ValueError: not enough values to unpack (expected 2, got 1)

The above exception was the direct cause of the following exception:

Traceback (most recent call last):
  File "C:\Users\User\AppData\Local\Programs\Python\Python312\Lib\site-packages\mpf\devices\switch.py", line 149, in _initialize
    self.hw_switch = self.platform.configure_switch(
                     ^^^^^^^^^^^^^^^^^^^^^^^^^^^^^^^
  File "C:\Users\User\AppData\Local\Programs\Python\Python312\Lib\site-packages\mpf\platforms\fast\fast.py", line 505, in configure_switch
    number = self._parse_switch_number(number)
             ^^^^^^^^^^^^^^^^^^^^^^^^^^^^^^^^^
  File "C:\Users\User\AppData\Local\Programs\Python\Python312\Lib\site-packages\mpf\platforms\fast\fast.py", line 441, in _parse_switch_number
    raise AssertionError(f"Switch {int(index, 16)} does not exist. Only "
AssertionError: Switch 51 does not exist. Only 0 switches found. Switch number: 51

The above exception was the direct cause of the following exception:

Traceback (most recent call last):
  File "C:\Users\User\AppData\Local\Programs\Python\Python312\Lib\site-packages\mpf\core\system_wide_device.py", line 17, in device_added_system_wide
    await self._initialize()
  File "C:\Users\User\AppData\Local\Programs\Python\Python312\Lib\site-packages\mpf\devices\switch.py", line 152, in _initialize
    raise ConfigFileError("Failed to configure switch {} in platform. See error above".format(self.name), 2,
mpf.exceptions.config_file_error.ConfigFileError: Config File Error in switch: Failed to configure switch s_pop_bumper_cc_2 in platform. See error above Error Code: CFE-switch-2 (https://missionpinball.org/logs)
2025-03-15 11:16:05,283 : ERROR : asyncio : Task exception was never retrieved
future: <Task finished name='Task-30' coro=<SystemWideDevice.device_added_system_wide() done, defined at C:\Users\User\AppData\Local\Programs\Python\Python312\Lib\site-packages\mpf\core\system_wide_device.py:15> exception=ConfigFileError('Failed to configure switch s_trough_ball_3 in platform. See error above')>
Traceback (most recent call last):
  File "C:\Users\User\AppData\Local\Programs\Python\Python312\Lib\site-packages\mpf\platforms\fast\fast.py", line 447, in _parse_switch_number
    board = self.io_boards_by_name[board_str]
            ~~~~~~~~~~~~~~~~~~~~~~^^^^^^^^^^^
KeyError: '3208'

During handling of the above exception, another exception occurred:

Traceback (most recent call last):
  File "C:\Users\User\AppData\Local\Programs\Python\Python312\Lib\site-packages\mpf\devices\switch.py", line 149, in _initialize
    self.hw_switch = self.platform.configure_switch(
                     ^^^^^^^^^^^^^^^^^^^^^^^^^^^^^^^
  File "C:\Users\User\AppData\Local\Programs\Python\Python312\Lib\site-packages\mpf\platforms\fast\fast.py", line 505, in configure_switch
    number = self._parse_switch_number(number)
             ^^^^^^^^^^^^^^^^^^^^^^^^^^^^^^^^^
  File "C:\Users\User\AppData\Local\Programs\Python\Python312\Lib\site-packages\mpf\platforms\fast\fast.py", line 449, in _parse_switch_number
    raise AssertionError(f"Board {board_str} does not exist for switch {number}")
AssertionError: Board 3208 does not exist for switch 3208-2

The above exception was the direct cause of the following exception:

Traceback (most recent call last):
  File "C:\Users\User\AppData\Local\Programs\Python\Python312\Lib\site-packages\mpf\core\system_wide_device.py", line 17, in device_added_system_wide
    await self._initialize()
  File "C:\Users\User\AppData\Local\Programs\Python\Python312\Lib\site-packages\mpf\devices\switch.py", line 152, in _initialize
    raise ConfigFileError("Failed to configure switch {} in platform. See error above".format(self.name), 2,
mpf.exceptions.config_file_error.ConfigFileError: Config File Error in switch: Failed to configure switch s_trough_ball_3 in platform. See error above Error Code: CFE-switch-2 (https://missionpinball.org/logs)
2025-03-15 11:16:05,284 : ERROR : asyncio : Task exception was never retrieved
future: <Task finished name='Task-41' coro=<SystemWideDevice.device_added_system_wide() done, defined at C:\Users\User\AppData\Local\Programs\Python\Python312\Lib\site-packages\mpf\core\system_wide_device.py:15> exception=ConfigFileError('Failed to configure switch s_pop_bumper_cc_3 in platform. See error above')>
Traceback (most recent call last):
  File "C:\Users\User\AppData\Local\Programs\Python\Python312\Lib\site-packages\mpf\platforms\fast\fast.py", line 433, in _parse_switch_number
    board_str, switch_str = number.split("-")
    ^^^^^^^^^^^^^^^^^^^^^
ValueError: not enough values to unpack (expected 2, got 1)

The above exception was the direct cause of the following exception:

Traceback (most recent call last):
  File "C:\Users\User\AppData\Local\Programs\Python\Python312\Lib\site-packages\mpf\devices\switch.py", line 149, in _initialize
    self.hw_switch = self.platform.configure_switch(
                     ^^^^^^^^^^^^^^^^^^^^^^^^^^^^^^^
  File "C:\Users\User\AppData\Local\Programs\Python\Python312\Lib\site-packages\mpf\platforms\fast\fast.py", line 505, in configure_switch
    number = self._parse_switch_number(number)
             ^^^^^^^^^^^^^^^^^^^^^^^^^^^^^^^^^
  File "C:\Users\User\AppData\Local\Programs\Python\Python312\Lib\site-packages\mpf\platforms\fast\fast.py", line 441, in _parse_switch_number
    raise AssertionError(f"Switch {int(index, 16)} does not exist. Only "
AssertionError: Switch 54 does not exist. Only 0 switches found. Switch number: 54

The above exception was the direct cause of the following exception:

Traceback (most recent call last):
  File "C:\Users\User\AppData\Local\Programs\Python\Python312\Lib\site-packages\mpf\core\system_wide_device.py", line 17, in device_added_system_wide
    await self._initialize()
  File "C:\Users\User\AppData\Local\Programs\Python\Python312\Lib\site-packages\mpf\devices\switch.py", line 152, in _initialize
    raise ConfigFileError("Failed to configure switch {} in platform. See error above".format(self.name), 2,
mpf.exceptions.config_file_error.ConfigFileError: Config File Error in switch: Failed to configure switch s_pop_bumper_cc_3 in platform. See error above Error Code: CFE-switch-2 (https://missionpinball.org/logs)
2025-03-15 11:16:05,286 : ERROR : asyncio : Task exception was never retrieved
future: <Task finished name='Task-39' coro=<SystemWideDevice.device_added_system_wide() done, defined at C:\Users\User\AppData\Local\Programs\Python\Python312\Lib\site-packages\mpf\core\system_wide_device.py:15> exception=ConfigFileError('Failed to configure switch s_pop_bumper_cc_1 in platform. See error above')>
Traceback (most recent call last):
  File "C:\Users\User\AppData\Local\Programs\Python\Python312\Lib\site-packages\mpf\platforms\fast\fast.py", line 433, in _parse_switch_number
    board_str, switch_str = number.split("-")
    ^^^^^^^^^^^^^^^^^^^^^
ValueError: not enough values to unpack (expected 2, got 1)

The above exception was the direct cause of the following exception:

Traceback (most recent call last):
  File "C:\Users\User\AppData\Local\Programs\Python\Python312\Lib\site-packages\mpf\devices\switch.py", line 149, in _initialize
    self.hw_switch = self.platform.configure_switch(
                     ^^^^^^^^^^^^^^^^^^^^^^^^^^^^^^^
  File "C:\Users\User\AppData\Local\Programs\Python\Python312\Lib\site-packages\mpf\platforms\fast\fast.py", line 505, in configure_switch
    number = self._parse_switch_number(number)
             ^^^^^^^^^^^^^^^^^^^^^^^^^^^^^^^^^
  File "C:\Users\User\AppData\Local\Programs\Python\Python312\Lib\site-packages\mpf\platforms\fast\fast.py", line 441, in _parse_switch_number
    raise AssertionError(f"Switch {int(index, 16)} does not exist. Only "
AssertionError: Switch 50 does not exist. Only 0 switches found. Switch number: 50

The above exception was the direct cause of the following exception:

Traceback (most recent call last):
  File "C:\Users\User\AppData\Local\Programs\Python\Python312\Lib\site-packages\mpf\core\system_wide_device.py", line 17, in device_added_system_wide
    await self._initialize()
  File "C:\Users\User\AppData\Local\Programs\Python\Python312\Lib\site-packages\mpf\devices\switch.py", line 152, in _initialize
    raise ConfigFileError("Failed to configure switch {} in platform. See error above".format(self.name), 2,
mpf.exceptions.config_file_error.ConfigFileError: Config File Error in switch: Failed to configure switch s_pop_bumper_cc_1 in platform. See error above Error Code: CFE-switch-2 (https://missionpinball.org/logs)
2025-03-15 11:16:05,287 : ERROR : asyncio : Task exception was never retrieved
future: <Task finished name='Task-42' coro=<SystemWideDevice.device_added_system_wide() done, defined at C:\Users\User\AppData\Local\Programs\Python\Python312\Lib\site-packages\mpf\core\system_wide_device.py:15> exception=ConfigFileError('Failed to configure switch s_pop_bumper_m in platform. See error above')>
Traceback (most recent call last):
  File "C:\Users\User\AppData\Local\Programs\Python\Python312\Lib\site-packages\mpf\platforms\fast\fast.py", line 433, in _parse_switch_number
    board_str, switch_str = number.split("-")
    ^^^^^^^^^^^^^^^^^^^^^
ValueError: not enough values to unpack (expected 2, got 1)

The above exception was the direct cause of the following exception:

Traceback (most recent call last):
  File "C:\Users\User\AppData\Local\Programs\Python\Python312\Lib\site-packages\mpf\devices\switch.py", line 149, in _initialize
    self.hw_switch = self.platform.configure_switch(
                     ^^^^^^^^^^^^^^^^^^^^^^^^^^^^^^^
  File "C:\Users\User\AppData\Local\Programs\Python\Python312\Lib\site-packages\mpf\platforms\fast\fast.py", line 505, in configure_switch
    number = self._parse_switch_number(number)
             ^^^^^^^^^^^^^^^^^^^^^^^^^^^^^^^^^
  File "C:\Users\User\AppData\Local\Programs\Python\Python312\Lib\site-packages\mpf\platforms\fast\fast.py", line 441, in _parse_switch_number
    raise AssertionError(f"Switch {int(index, 16)} does not exist. Only "
AssertionError: Switch 52 does not exist. Only 0 switches found. Switch number: 52

The above exception was the direct cause of the following exception:

Traceback (most recent call last):
  File "C:\Users\User\AppData\Local\Programs\Python\Python312\Lib\site-packages\mpf\core\system_wide_device.py", line 17, in device_added_system_wide
    await self._initialize()
  File "C:\Users\User\AppData\Local\Programs\Python\Python312\Lib\site-packages\mpf\devices\switch.py", line 152, in _initialize
    raise ConfigFileError("Failed to configure switch {} in platform. See error above".format(self.name), 2,
mpf.exceptions.config_file_error.ConfigFileError: Config File Error in switch: Failed to configure switch s_pop_bumper_m in platform. See error above Error Code: CFE-switch-2 (https://missionpinball.org/logs)
2025-03-15 11:16:05,288 : ERROR : asyncio : Task exception was never retrieved
future: <Task finished name='Task-31' coro=<SystemWideDevice.device_added_system_wide() done, defined at C:\Users\User\AppData\Local\Programs\Python\Python312\Lib\site-packages\mpf\core\system_wide_device.py:15> exception=ConfigFileError('Failed to configure switch s_trough_ball_4 in platform. See error above')>
Traceback (most recent call last):
  File "C:\Users\User\AppData\Local\Programs\Python\Python312\Lib\site-packages\mpf\platforms\fast\fast.py", line 447, in _parse_switch_number
    board = self.io_boards_by_name[board_str]
            ~~~~~~~~~~~~~~~~~~~~~~^^^^^^^^^^^
KeyError: '3208'

During handling of the above exception, another exception occurred:

Traceback (most recent call last):
  File "C:\Users\User\AppData\Local\Programs\Python\Python312\Lib\site-packages\mpf\devices\switch.py", line 149, in _initialize
    self.hw_switch = self.platform.configure_switch(
                     ^^^^^^^^^^^^^^^^^^^^^^^^^^^^^^^
  File "C:\Users\User\AppData\Local\Programs\Python\Python312\Lib\site-packages\mpf\platforms\fast\fast.py", line 505, in configure_switch
    number = self._parse_switch_number(number)
             ^^^^^^^^^^^^^^^^^^^^^^^^^^^^^^^^^
  File "C:\Users\User\AppData\Local\Programs\Python\Python312\Lib\site-packages\mpf\platforms\fast\fast.py", line 449, in _parse_switch_number
    raise AssertionError(f"Board {board_str} does not exist for switch {number}")
AssertionError: Board 3208 does not exist for switch 3208-3

The above exception was the direct cause of the following exception:

Traceback (most recent call last):
  File "C:\Users\User\AppData\Local\Programs\Python\Python312\Lib\site-packages\mpf\core\system_wide_device.py", line 17, in device_added_system_wide
    await self._initialize()
  File "C:\Users\User\AppData\Local\Programs\Python\Python312\Lib\site-packages\mpf\devices\switch.py", line 152, in _initialize
    raise ConfigFileError("Failed to configure switch {} in platform. See error above".format(self.name), 2,
mpf.exceptions.config_file_error.ConfigFileError: Config File Error in switch: Failed to configure switch s_trough_ball_4 in platform. See error above Error Code: CFE-switch-2 (https://missionpinball.org/logs)
2025-03-15 11:16:05,290 : ERROR : asyncio : Task exception was never retrieved
future: <Task finished name='Task-43' coro=<SystemWideDevice.device_added_system_wide() done, defined at C:\Users\User\AppData\Local\Programs\Python\Python312\Lib\site-packages\mpf\core\system_wide_device.py:15> exception=ConfigFileError('Failed to configure switch s_slingshot_1 in platform. See error above')>
Traceback (most recent call last):
  File "C:\Users\User\AppData\Local\Programs\Python\Python312\Lib\site-packages\mpf\platforms\fast\fast.py", line 433, in _parse_switch_number
    board_str, switch_str = number.split("-")
    ^^^^^^^^^^^^^^^^^^^^^
ValueError: not enough values to unpack (expected 2, got 1)

The above exception was the direct cause of the following exception:

Traceback (most recent call last):
  File "C:\Users\User\AppData\Local\Programs\Python\Python312\Lib\site-packages\mpf\devices\switch.py", line 149, in _initialize
    self.hw_switch = self.platform.configure_switch(
                     ^^^^^^^^^^^^^^^^^^^^^^^^^^^^^^^
  File "C:\Users\User\AppData\Local\Programs\Python\Python312\Lib\site-packages\mpf\platforms\fast\fast.py", line 505, in configure_switch
    number = self._parse_switch_number(number)
             ^^^^^^^^^^^^^^^^^^^^^^^^^^^^^^^^^
  File "C:\Users\User\AppData\Local\Programs\Python\Python312\Lib\site-packages\mpf\platforms\fast\fast.py", line 441, in _parse_switch_number
    raise AssertionError(f"Switch {int(index, 16)} does not exist. Only "
AssertionError: Switch 17 does not exist. Only 0 switches found. Switch number: 17

The above exception was the direct cause of the following exception:

Traceback (most recent call last):
  File "C:\Users\User\AppData\Local\Programs\Python\Python312\Lib\site-packages\mpf\core\system_wide_device.py", line 17, in device_added_system_wide
    await self._initialize()
  File "C:\Users\User\AppData\Local\Programs\Python\Python312\Lib\site-packages\mpf\devices\switch.py", line 152, in _initialize
    raise ConfigFileError("Failed to configure switch {} in platform. See error above".format(self.name), 2,
mpf.exceptions.config_file_error.ConfigFileError: Config File Error in switch: Failed to configure switch s_slingshot_1 in platform. See error above Error Code: CFE-switch-2 (https://missionpinball.org/logs)
2025-03-15 11:16:05,297 : INFO : Machine : Starting the main run loop with active modes: []
2025-03-15 11:16:05,298 : WARNING : Machine : Attract mode is not active, game will not be playable. Please check your attract mode configuration.
2025-03-15 11:16:05,299 : INFO : Machine : Shutting down...
2025-03-15 11:16:05,299 : INFO : EventManager : Event: ======'shutdown'====== Args={}
2025-03-15 11:16:06,402 : ERROR : Machine : Runtime Exception
Traceback (most recent call last):
  File "C:\Users\User\AppData\Local\Programs\Python\Python312\Lib\site-packages\mpf\platforms\fast\fast.py", line 447, in _parse_switch_number
    board = self.io_boards_by_name[board_str]
            ~~~~~~~~~~~~~~~~~~~~~~^^^^^^^^^^^
KeyError: '3208'

During handling of the above exception, another exception occurred:

Traceback (most recent call last):
  File "C:\Users\User\AppData\Local\Programs\Python\Python312\Lib\site-packages\mpf\devices\switch.py", line 149, in _initialize
    self.hw_switch = self.platform.configure_switch(
                     ^^^^^^^^^^^^^^^^^^^^^^^^^^^^^^^
  File "C:\Users\User\AppData\Local\Programs\Python\Python312\Lib\site-packages\mpf\platforms\fast\fast.py", line 505, in configure_switch
    number = self._parse_switch_number(number)
             ^^^^^^^^^^^^^^^^^^^^^^^^^^^^^^^^^
  File "C:\Users\User\AppData\Local\Programs\Python\Python312\Lib\site-packages\mpf\platforms\fast\fast.py", line 449, in _parse_switch_number
    raise AssertionError(f"Board {board_str} does not exist for switch {number}")
AssertionError: Board 3208 does not exist for switch 3208-4

The above exception was the direct cause of the following exception:

Traceback (most recent call last):
  File "C:\Users\User\AppData\Local\Programs\Python\Python312\Lib\site-packages\mpf\core\machine.py", line 808, in _run_loop
    raise self._exception['exception']
  File "C:\Users\User\AppData\Local\Programs\Python\Python312\Lib\site-packages\mpf\core\system_wide_device.py", line 17, in device_added_system_wide
    await self._initialize()
  File "C:\Users\User\AppData\Local\Programs\Python\Python312\Lib\site-packages\mpf\devices\switch.py", line 152, in _initialize
    raise ConfigFileError("Failed to configure switch {} in platform. See error above".format(self.name), 2,
mpf.exceptions.config_file_error.ConfigFileError: Config File Error in switch: Failed to configure switch s_trough_ball_5 in platform. See error above Error Code: CFE-switch-2 (https://missionpinball.org/logs)
2025-03-15 11:16:06,406 : INFO : root : MPF run loop ended.
