2025-03-14 21:00:20,102 : INFO : root : Loading config.
2025-03-14 21:00:20,109 : INFO : YamlMultifileConfigLoader : Machine config file #1: config.yaml
2025-03-14 21:00:20,110 : INFO : ConfigProcessor : Loading config from cache: C:\Users\User\AppData\Local\Temp\5682b9bdeb2b9ad8a31c13560e038609.mpf_cache
2025-03-14 21:00:20,144 : WARNING : ConfigProcessor : Config file in cache changed: C:\Users\User\Desktop\fast_homebrew_godot_v2\fast_homebrew_godot_v2\config\coils.yaml
2025-03-14 21:00:20,144 : INFO : ConfigProcessor : Loading config from file C:\Users\User\AppData\Local\Programs\Python\Python312\Lib\site-packages\mpf\mpfconfig.yaml.
2025-03-14 21:00:20,178 : INFO : ConfigProcessor : Loading config: C:\Users\User\AppData\Local\Programs\Python\Python312\Lib\site-packages\mpf\mpfconfig.yaml
2025-03-14 21:00:20,178 : INFO : ConfigProcessor : Loading config from file C:\Users\User\Desktop\fast_homebrew_godot_v2\fast_homebrew_godot_v2\config\config.yaml.
2025-03-14 21:00:20,186 : INFO : ConfigProcessor : Loading config: C:\Users\User\Desktop\fast_homebrew_godot_v2\fast_homebrew_godot_v2\config\config.yaml
2025-03-14 21:00:20,187 : INFO : ConfigProcessor : Loading config: C:\Users\User\Desktop\fast_homebrew_godot_v2\fast_homebrew_godot_v2\config\lights.yaml
2025-03-14 21:00:20,190 : INFO : ConfigProcessor : Loading config: C:\Users\User\Desktop\fast_homebrew_godot_v2\fast_homebrew_godot_v2\config\coils.yaml
2025-03-14 21:00:20,193 : INFO : ConfigProcessor : Loading config: C:\Users\User\Desktop\fast_homebrew_godot_v2\fast_homebrew_godot_v2\config\switches.yaml
2025-03-14 21:00:20,195 : INFO : ConfigProcessor : Loading config: C:\Users\User\Desktop\fast_homebrew_godot_v2\fast_homebrew_godot_v2\config\images.yaml
2025-03-14 21:00:20,197 : INFO : ConfigProcessor : Loading config: C:\Users\User\Desktop\fast_homebrew_godot_v2\fast_homebrew_godot_v2\config\videos.yaml
2025-03-14 21:00:20,203 : INFO : ConfigProcessor : Config file cache created: C:\Users\User\AppData\Local\Temp\5682b9bdeb2b9ad8a31c13560e038609.mpf_cache
2025-03-14 21:00:20,421 : INFO : ConfigProcessor : Loading config from cache: C:\Users\User\AppData\Local\Temp\8422c6572f827355f8aade1949d04025.mpf_cache
2025-03-14 21:00:20,423 : INFO : ConfigProcessor : Loading config from cache: C:\Users\User\AppData\Local\Temp\1c0e7e9816717d8e62c4728dfe372999.mpf_cache
2025-03-14 21:00:20,424 : INFO : ConfigProcessor : Loading config from cache: C:\Users\User\AppData\Local\Temp\e3e8065d662ad307fa9574659e7e4e8e.mpf_cache
2025-03-14 21:00:20,426 : INFO : ConfigProcessor : Loading config from cache: C:\Users\User\AppData\Local\Temp\8422c6572f827355f8aade1949d04025.mpf_cache
2025-03-14 21:00:20,427 : INFO : Machine : Mission Pinball Framework Core Engine v0.80.0.dev6
2025-03-14 21:00:20,428 : INFO : Machine : Command line arguments: {'no_load_cache': False, 'create_config_cache': True, 'bcp': False, 'configfile': ['config.yaml'], 'force_assets_load': False, 'platform_integration_test': False, 'jsonlogging': False, 'logfile': 'logs\\2025-03-14-21-00-20-mpf-BERNIE.log', 'pause': False, 'production': False, 'text_ui': False, 'loglevel': 15, 'consoleloglevel': 20, 'force_platform': None, 'syslog_address': None, 'full_logfile_path': 'C:\\Users\\User\\Desktop\\fast_homebrew_godot_v2\\fast_homebrew_godot_v2\\logs\\2025-03-14-21-00-20-mpf-BERNIE.log'}
2025-03-14 21:00:20,428 : INFO : Machine : MPF path: C:\Users\User\AppData\Local\Programs\Python\Python312\Lib\site-packages\mpf
2025-03-14 21:00:20,428 : INFO : Machine : Machine path: C:\Users\User\Desktop\fast_homebrew_godot_v2\fast_homebrew_godot_v2
2025-03-14 21:00:20,428 : INFO : Machine : Platform: win32
2025-03-14 21:00:20,428 : INFO : Machine : Python executable location: C:\Users\User\AppData\Local\Programs\Python\Python312\python.exe
2025-03-14 21:00:20,428 : INFO : Machine : Python version: 3.12.3 (64-bit)
2025-03-14 21:00:20,436 : INFO : Machine : Initializing MPF...
2025-03-14 21:00:20,648 : INFO : FAST : Auto-detecting ports for the following connections: ['net']
2025-03-14 21:00:20,692 : INFO : FAST : Detected NET on port COM5
2025-03-14 21:00:20,806 : INFO : FAST [NET] : Trying to connect to COM5 at 921600bps
2025-03-14 21:00:20,813 : INFO : FAST [NET] : Connected to COM5 at 921600bps
2025-03-14 21:00:20,819 : INFO : FAST [NET] : Connected to FP-CPU-2000 with firmware v02.26
2025-03-14 21:00:20,850 : INFO : FAST [NET] : Registered I/O Board 0: Model: FP-I/O-3208, Firmware: 01.10, Switches: 32, Drivers: 8
2025-03-14 21:00:20,850 : INFO : EventManager : Event: ======'machine_var_credits_string'====== Args={'value': 'FREE PLAY', 'prev_value': None, 'change': True}
2025-03-14 21:00:20,908 : INFO : EventManager : Event: ======'machine_var_master_volume'====== Args={'value': 0.5, 'prev_value': None, 'change': True}
2025-03-14 21:00:20,908 : INFO : EventManager : Event: ======'machine_var_mpf_version'====== Args={'value': 'Mission Pinball Framework v0.80.0.dev6', 'prev_value': None, 'change': True}
2025-03-14 21:00:20,908 : INFO : EventManager : Event: ======'machine_var_mpf_extended_version'====== Args={'value': 'Mission Pinball Framework v0.80.0.dev6, Config version:6, Show version: 6, BCP version:1.1', 'prev_value': None, 'change': True}
2025-03-14 21:00:20,909 : INFO : EventManager : Event: ======'machine_var_python_version'====== Args={'value': '3.12.3', 'prev_value': None, 'change': True}
2025-03-14 21:00:21,050 : INFO : EventManager : Event: ======'machine_var_platform'====== Args={'value': 'Windows-11-10.0.22631-SP0', 'prev_value': None, 'change': True}
2025-03-14 21:00:21,051 : INFO : EventManager : Event: ======'machine_var_platform_system'====== Args={'value': 'Windows', 'prev_value': None, 'change': True}
2025-03-14 21:00:21,051 : INFO : EventManager : Event: ======'machine_var_platform_release'====== Args={'value': '11', 'prev_value': None, 'change': True}
2025-03-14 21:00:21,051 : INFO : EventManager : Event: ======'machine_var_platform_version'====== Args={'value': '10.0.22631', 'prev_value': None, 'change': True}
2025-03-14 21:00:21,051 : INFO : EventManager : Event: ======'machine_var_platform_machine'====== Args={'value': 'AMD64', 'prev_value': None, 'change': True}
2025-03-14 21:00:21,051 : INFO : EventManager : Event: ======'machine_var_log_file_path'====== Args={'value': 'C:\\Users\\User\\Desktop\\fast_homebrew_godot_v2\\fast_homebrew_godot_v2\\logs\\2025-03-14-21-00-20-mpf-BERNIE.log', 'prev_value': None, 'change': True}
2025-03-14 21:00:21,051 : INFO : EventManager : Event: ======'init_phase_1'====== Args={}
2025-03-14 21:00:25,107 : INFO : SwitchController : <<<<<<< 's_flipper_left' active >>>>>>>
2025-03-14 21:00:25,107 : INFO : SwitchController : <<<<<<< 's_flipper_right' active >>>>>>>
2025-03-14 21:00:25,108 : INFO : EventManager : Event: ======'init_phase_2'====== Args={}
2025-03-14 21:00:25,108 : INFO : SwitchController : Found active switch: (30, [FAST Platform Interface]) <switch.s_flipper_left>
2025-03-14 21:00:25,109 : INFO : SwitchController : Found active switch: (31, [FAST Platform Interface]) <switch.s_flipper_right>
2025-03-14 21:00:25,116 : ERROR : asyncio : Task exception was never retrieved
future: <Task finished name='Task-41' coro=<BallDevice._initialize_async() done, defined at C:\Users\User\AppData\Local\Programs\Python\Python312\Lib\site-packages\mpf\devices\ball_device\ball_device.py:196> exception=ConfigFileError('Config validation error: Entry ball_device_counter_ball_switches:ball_device_counter_ball_switches:ball_switches = "s_trough_ball_1" is not valid. Device "s_trough_ball_1" not found in "switches:" section in your config.')>
Traceback (most recent call last):
  File "C:\Users\User\AppData\Local\Programs\Python\Python312\Lib\site-packages\mpf\devices\ball_device\ball_device.py", line 198, in _initialize_async
    await self.ball_count_handler.initialize()
  File "C:\Users\User\AppData\Local\Programs\Python\Python312\Lib\site-packages\mpf\devices\ball_device\ball_count_handler.py", line 92, in initialize
    self.counter = counter_class(self.ball_device, self.ball_device.config.get("counter", {}))
                   ^^^^^^^^^^^^^^^^^^^^^^^^^^^^^^^^^^^^^^^^^^^^^^^^^^^^^^^^^^^^^^^^^^^^^^^^^^^
  File "C:\Users\User\AppData\Local\Programs\Python\Python312\Lib\site-packages\mpf\devices\ball_device\switch_counter.py", line 27, in __init__
    self.config = self.machine.config_validator.validate_config("ball_device_counter_ball_switches", self.config)
                  ^^^^^^^^^^^^^^^^^^^^^^^^^^^^^^^^^^^^^^^^^^^^^^^^^^^^^^^^^^^^^^^^^^^^^^^^^^^^^^^^^^^^^^^^^^^^^^^
  File "C:\Users\User\AppData\Local\Programs\Python\Python312\Lib\site-packages\mpf\core\config_validator.py", line 164, in validate_config
    return self._validate_config(config_spec, source, base_spec=base_spec, add_missing_keys=add_missing_keys,
           ^^^^^^^^^^^^^^^^^^^^^^^^^^^^^^^^^^^^^^^^^^^^^^^^^^^^^^^^^^^^^^^^^^^^^^^^^^^^^^^^^^^^^^^^^^^^^^^^^^
  File "C:\Users\User\AppData\Local\Programs\Python\Python312\Lib\site-packages\mpf\core\config_validator.py", line 204, in _validate_config
    processed_config[k] = self.validate_config_item(
                          ^^^^^^^^^^^^^^^^^^^^^^^^^^
  File "C:\Users\User\AppData\Local\Programs\Python\Python312\Lib\site-packages\mpf\core\config_validator.py", line 256, in validate_config_item
    new_list.append(self.validate_item(i, validation, validation_failure_info))
                    ^^^^^^^^^^^^^^^^^^^^^^^^^^^^^^^^^^^^^^^^^^^^^^^^^^^^^^^^^^
  File "C:\Users\User\AppData\Local\Programs\Python\Python312\Lib\site-packages\mpf\core\config_validator.py", line 699, in validate_item
    return self.validator_list[validator](item, validation_failure_info=validation_failure_info, param=param)
           ^^^^^^^^^^^^^^^^^^^^^^^^^^^^^^^^^^^^^^^^^^^^^^^^^^^^^^^^^^^^^^^^^^^^^^^^^^^^^^^^^^^^^^^^^^^^^^^^^^
  File "C:\Users\User\AppData\Local\Programs\Python\Python312\Lib\site-packages\mpf\core\config_validator.py", line 413, in _validate_type_machine
    raise self.validation_error(item, validation_failure_info,
mpf.exceptions.config_file_error.ConfigFileError: Config File Error in ConfigValidator: Config validation error: Entry ball_device_counter_ball_switches:ball_device_counter_ball_switches:ball_switches = "s_trough_ball_1" is not valid. Device "s_trough_ball_1" not found in "switches:" section in your config. Error Code: CFE-ConfigValidator-6 (https://missionpinball.org/logs)
2025-03-14 21:00:25,189 : INFO : ball_device.bd_plunger : BCH: Initial count: 0
2025-03-14 21:00:25,189 : INFO : Machine : Starting the main run loop with active modes: []
2025-03-14 21:00:25,189 : WARNING : Machine : Attract mode is not active, game will not be playable. Please check your attract mode configuration.
2025-03-14 21:00:25,189 : INFO : ball_device.bd_plunger : State: idle
2025-03-14 21:00:25,192 : INFO : Machine : Shutting down...
2025-03-14 21:00:25,192 : INFO : EventManager : Event: ======'shutdown'====== Args={}
2025-03-14 21:00:25,224 : INFO : EventManager : Event: ======'init_phase_3'====== Args={}
2025-03-14 21:00:25,228 : INFO : EventManager : Event: ======'init_phase_4'====== Args={}
2025-03-14 21:00:25,230 : ERROR : asyncio : Exception in callback Util.raise_exceptions(<Task finishe...unt_stable'")>) at C:\Users\User\AppData\Local\Programs\Python\Python312\Lib\site-packages\mpf\core\utility_functions.py:789
handle: <Handle Util.raise_exceptions(<Task finishe...unt_stable'")>) at C:\Users\User\AppData\Local\Programs\Python\Python312\Lib\site-packages\mpf\core\utility_functions.py:789>
Traceback (most recent call last):
  File "C:\Users\User\AppData\Local\Programs\Python\Python312\Lib\asyncio\events.py", line 88, in _run
    self._context.run(self._callback, *self._args)
  File "C:\Users\User\AppData\Local\Programs\Python\Python312\Lib\site-packages\mpf\core\utility_functions.py", line 797, in raise_exceptions
    future.result()
  File "C:\Users\User\AppData\Local\Programs\Python\Python312\Lib\site-packages\mpf\core\ball_controller.py", line 90, in _add_new_balls_to_playfield
    self.num_balls_known = await self._count_all_balls_in_devices()
                           ^^^^^^^^^^^^^^^^^^^^^^^^^^^^^^^^^^^^^^^^
  File "C:\Users\User\AppData\Local\Programs\Python\Python312\Lib\site-packages\mpf\core\ball_controller.py", line 129, in _count_all_balls_in_devices
    futures.append(asyncio.ensure_future(device.ball_count_handler.counter.wait_for_count_stable()))
                                         ^^^^^^^^^^^^^^^^^^^^^^^^^^^^^^^^^^^^^^^^^^^^^^^^^^^^^^^
AttributeError: 'NoneType' object has no attribute 'wait_for_count_stable'
2025-03-14 21:00:25,304 : ERROR : asyncio : Exception in callback EventManager._queue_task_done(<Task finishe...right_full>')>)
handle: <Handle EventManager._queue_task_done(<Task finishe...right_full>')>)>
Traceback (most recent call last):
  File "C:\Users\User\AppData\Local\Programs\Python\Python312\Lib\asyncio\events.py", line 88, in _run
    self._context.run(self._callback, *self._args)
  File "C:\Users\User\AppData\Local\Programs\Python\Python312\Lib\site-packages\mpf\core\events.py", line 795, in _queue_task_done
    future.result()
  File "C:\Users\User\AppData\Local\Programs\Python\Python312\Lib\site-packages\mpf\core\events.py", line 708, in _run_handlers_sequential
    handler.callback(queue=queue, **merged_kwargs)
  File "C:\Users\User\AppData\Local\Programs\Python\Python312\Lib\site-packages\mpf\devices\driver.py", line 58, in _check_duplicate_coil_numbers
    raise AssertionError("Duplicate coil number {} for coil {}".format(coil.hw_driver.number, coil))
AssertionError: Duplicate coil number 1 for coil <coil.c_flipper_right_full>
2025-03-14 21:00:26,326 : ERROR : asyncio : Task was destroyed but it is pending!
task: <Task pending name='Task-59' coro=<IocpProactor.accept.<locals>.accept_coro() running at C:\Users\User\AppData\Local\Programs\Python\Python312\Lib\asyncio\windows_events.py:566> wait_for=<_OverlappedFuture cancelled>>
2025-03-14 21:00:26,329 : ERROR : Machine : Runtime Exception
Traceback (most recent call last):
  File "C:\Users\User\AppData\Local\Programs\Python\Python312\Lib\site-packages\mpf\core\machine.py", line 808, in _run_loop
    raise self._exception['exception']
  File "C:\Users\User\AppData\Local\Programs\Python\Python312\Lib\site-packages\mpf\devices\ball_device\ball_device.py", line 198, in _initialize_async
    await self.ball_count_handler.initialize()
  File "C:\Users\User\AppData\Local\Programs\Python\Python312\Lib\site-packages\mpf\devices\ball_device\ball_count_handler.py", line 92, in initialize
    self.counter = counter_class(self.ball_device, self.ball_device.config.get("counter", {}))
                   ^^^^^^^^^^^^^^^^^^^^^^^^^^^^^^^^^^^^^^^^^^^^^^^^^^^^^^^^^^^^^^^^^^^^^^^^^^^
  File "C:\Users\User\AppData\Local\Programs\Python\Python312\Lib\site-packages\mpf\devices\ball_device\switch_counter.py", line 27, in __init__
    self.config = self.machine.config_validator.validate_config("ball_device_counter_ball_switches", self.config)
                  ^^^^^^^^^^^^^^^^^^^^^^^^^^^^^^^^^^^^^^^^^^^^^^^^^^^^^^^^^^^^^^^^^^^^^^^^^^^^^^^^^^^^^^^^^^^^^^^
  File "C:\Users\User\AppData\Local\Programs\Python\Python312\Lib\site-packages\mpf\core\config_validator.py", line 164, in validate_config
    return self._validate_config(config_spec, source, base_spec=base_spec, add_missing_keys=add_missing_keys,
           ^^^^^^^^^^^^^^^^^^^^^^^^^^^^^^^^^^^^^^^^^^^^^^^^^^^^^^^^^^^^^^^^^^^^^^^^^^^^^^^^^^^^^^^^^^^^^^^^^^
  File "C:\Users\User\AppData\Local\Programs\Python\Python312\Lib\site-packages\mpf\core\config_validator.py", line 204, in _validate_config
    processed_config[k] = self.validate_config_item(
                          ^^^^^^^^^^^^^^^^^^^^^^^^^^
  File "C:\Users\User\AppData\Local\Programs\Python\Python312\Lib\site-packages\mpf\core\config_validator.py", line 256, in validate_config_item
    new_list.append(self.validate_item(i, validation, validation_failure_info))
                    ^^^^^^^^^^^^^^^^^^^^^^^^^^^^^^^^^^^^^^^^^^^^^^^^^^^^^^^^^^
  File "C:\Users\User\AppData\Local\Programs\Python\Python312\Lib\site-packages\mpf\core\config_validator.py", line 699, in validate_item
    return self.validator_list[validator](item, validation_failure_info=validation_failure_info, param=param)
           ^^^^^^^^^^^^^^^^^^^^^^^^^^^^^^^^^^^^^^^^^^^^^^^^^^^^^^^^^^^^^^^^^^^^^^^^^^^^^^^^^^^^^^^^^^^^^^^^^^
  File "C:\Users\User\AppData\Local\Programs\Python\Python312\Lib\site-packages\mpf\core\config_validator.py", line 413, in _validate_type_machine
    raise self.validation_error(item, validation_failure_info,
mpf.exceptions.config_file_error.ConfigFileError: Config File Error in ConfigValidator: Config validation error: Entry ball_device_counter_ball_switches:ball_device_counter_ball_switches:ball_switches = "s_trough_ball_1" is not valid. Device "s_trough_ball_1" not found in "switches:" section in your config. Error Code: CFE-ConfigValidator-6 (https://missionpinball.org/logs)
2025-03-14 21:00:26,334 : INFO : root : MPF run loop ended.
