2025-03-14 20:29:11,630 : INFO : root : Loading config.
2025-03-14 20:29:11,638 : INFO : YamlMultifileConfigLoader : Machine config file #1: config.yaml
2025-03-14 20:29:11,639 : INFO : ConfigProcessor : Loading config from cache: C:\Users\User\AppData\Local\Temp\5682b9bdeb2b9ad8a31c13560e038609.mpf_cache
2025-03-14 20:29:11,663 : WARNING : ConfigProcessor : Config file in cache changed: C:\Users\User\Desktop\fast_homebrew_godot_v2\fast_homebrew_godot_v2\config\switches.yaml
2025-03-14 20:29:11,663 : INFO : ConfigProcessor : Loading config from file C:\Users\User\AppData\Local\Programs\Python\Python312\Lib\site-packages\mpf\mpfconfig.yaml.
2025-03-14 20:29:11,696 : INFO : ConfigProcessor : Loading config: C:\Users\User\AppData\Local\Programs\Python\Python312\Lib\site-packages\mpf\mpfconfig.yaml
2025-03-14 20:29:11,697 : INFO : ConfigProcessor : Loading config from file C:\Users\User\Desktop\fast_homebrew_godot_v2\fast_homebrew_godot_v2\config\config.yaml.
2025-03-14 20:29:11,705 : INFO : ConfigProcessor : Loading config: C:\Users\User\Desktop\fast_homebrew_godot_v2\fast_homebrew_godot_v2\config\config.yaml
2025-03-14 20:29:11,707 : INFO : ConfigProcessor : Loading config: C:\Users\User\Desktop\fast_homebrew_godot_v2\fast_homebrew_godot_v2\config\lights.yaml
2025-03-14 20:29:11,709 : INFO : ConfigProcessor : Loading config: C:\Users\User\Desktop\fast_homebrew_godot_v2\fast_homebrew_godot_v2\config\coils.yaml
2025-03-14 20:29:11,712 : INFO : ConfigProcessor : Loading config: C:\Users\User\Desktop\fast_homebrew_godot_v2\fast_homebrew_godot_v2\config\switches.yaml
2025-03-14 20:29:11,714 : INFO : ConfigProcessor : Loading config: C:\Users\User\Desktop\fast_homebrew_godot_v2\fast_homebrew_godot_v2\config\images.yaml
2025-03-14 20:29:11,720 : INFO : ConfigProcessor : Loading config: C:\Users\User\Desktop\fast_homebrew_godot_v2\fast_homebrew_godot_v2\config\videos.yaml
2025-03-14 20:29:11,723 : INFO : ConfigProcessor : Config file cache created: C:\Users\User\AppData\Local\Temp\5682b9bdeb2b9ad8a31c13560e038609.mpf_cache
2025-03-14 20:29:11,936 : INFO : ConfigProcessor : Loading config from cache: C:\Users\User\AppData\Local\Temp\8422c6572f827355f8aade1949d04025.mpf_cache
2025-03-14 20:29:11,938 : INFO : ConfigProcessor : Loading config from cache: C:\Users\User\AppData\Local\Temp\1c0e7e9816717d8e62c4728dfe372999.mpf_cache
2025-03-14 20:29:11,940 : INFO : ConfigProcessor : Loading config from cache: C:\Users\User\AppData\Local\Temp\e3e8065d662ad307fa9574659e7e4e8e.mpf_cache
2025-03-14 20:29:11,942 : INFO : ConfigProcessor : Loading config from cache: C:\Users\User\AppData\Local\Temp\8422c6572f827355f8aade1949d04025.mpf_cache
2025-03-14 20:29:11,944 : INFO : Machine : Mission Pinball Framework Core Engine v0.80.0.dev6
2025-03-14 20:29:11,944 : INFO : Machine : Command line arguments: {'no_load_cache': False, 'create_config_cache': True, 'bcp': False, 'configfile': ['config.yaml'], 'force_assets_load': False, 'platform_integration_test': False, 'jsonlogging': False, 'logfile': 'logs\\2025-03-14-20-29-11-mpf-BERNIE.log', 'pause': False, 'production': False, 'text_ui': False, 'loglevel': 15, 'consoleloglevel': 20, 'force_platform': None, 'syslog_address': None, 'full_logfile_path': 'C:\\Users\\User\\Desktop\\fast_homebrew_godot_v2\\fast_homebrew_godot_v2\\logs\\2025-03-14-20-29-11-mpf-BERNIE.log'}
2025-03-14 20:29:11,944 : INFO : Machine : MPF path: C:\Users\User\AppData\Local\Programs\Python\Python312\Lib\site-packages\mpf
2025-03-14 20:29:11,944 : INFO : Machine : Machine path: C:\Users\User\Desktop\fast_homebrew_godot_v2\fast_homebrew_godot_v2
2025-03-14 20:29:11,944 : INFO : Machine : Platform: win32
2025-03-14 20:29:11,944 : INFO : Machine : Python executable location: C:\Users\User\AppData\Local\Programs\Python\Python312\python.exe
2025-03-14 20:29:11,945 : INFO : Machine : Python version: 3.12.3 (64-bit)
2025-03-14 20:29:11,948 : INFO : Machine : Initializing MPF...
2025-03-14 20:29:12,184 : INFO : FAST : Auto-detecting ports for the following connections: ['net']
2025-03-14 20:29:12,235 : INFO : FAST : Detected NET on port COM5
2025-03-14 20:29:12,347 : INFO : FAST [NET] : Trying to connect to COM5 at 921600bps
2025-03-14 20:29:12,354 : INFO : FAST [NET] : Connected to COM5 at 921600bps
2025-03-14 20:29:12,358 : INFO : FAST [NET] : Connected to FP-CPU-2000 with firmware v02.26
2025-03-14 20:29:12,390 : INFO : EventManager : Event: ======'machine_var_credits_string'====== Args={'value': 'FREE PLAY', 'prev_value': None, 'change': True}
2025-03-14 20:29:12,448 : INFO : EventManager : Event: ======'machine_var_master_volume'====== Args={'value': 0.5, 'prev_value': None, 'change': True}
2025-03-14 20:29:12,448 : INFO : EventManager : Event: ======'machine_var_mpf_version'====== Args={'value': 'Mission Pinball Framework v0.80.0.dev6', 'prev_value': None, 'change': True}
2025-03-14 20:29:12,448 : INFO : EventManager : Event: ======'machine_var_mpf_extended_version'====== Args={'value': 'Mission Pinball Framework v0.80.0.dev6, Config version:6, Show version: 6, BCP version:1.1', 'prev_value': None, 'change': True}
2025-03-14 20:29:12,449 : INFO : EventManager : Event: ======'machine_var_python_version'====== Args={'value': '3.12.3', 'prev_value': None, 'change': True}
2025-03-14 20:29:12,703 : INFO : EventManager : Event: ======'machine_var_platform'====== Args={'value': 'Windows-11-10.0.22631-SP0', 'prev_value': None, 'change': True}
2025-03-14 20:29:12,703 : INFO : EventManager : Event: ======'machine_var_platform_system'====== Args={'value': 'Windows', 'prev_value': None, 'change': True}
2025-03-14 20:29:12,703 : INFO : EventManager : Event: ======'machine_var_platform_release'====== Args={'value': '11', 'prev_value': None, 'change': True}
2025-03-14 20:29:12,704 : INFO : EventManager : Event: ======'machine_var_platform_version'====== Args={'value': '10.0.22631', 'prev_value': None, 'change': True}
2025-03-14 20:29:12,704 : INFO : EventManager : Event: ======'machine_var_platform_machine'====== Args={'value': 'AMD64', 'prev_value': None, 'change': True}
2025-03-14 20:29:12,704 : INFO : EventManager : Event: ======'machine_var_log_file_path'====== Args={'value': 'C:\\Users\\User\\Desktop\\fast_homebrew_godot_v2\\fast_homebrew_godot_v2\\logs\\2025-03-14-20-29-11-mpf-BERNIE.log', 'prev_value': None, 'change': True}
2025-03-14 20:29:12,704 : INFO : EventManager : Event: ======'init_phase_1'====== Args={}
2025-03-14 20:29:12,744 : ERROR : asyncio : Task exception was never retrieved
future: <Task finished name='Task-20' coro=<SystemWideDevice.device_added_system_wide() done, defined at C:\Users\User\AppData\Local\Programs\Python\Python312\Lib\site-packages\mpf\core\system_wide_device.py:15> exception=ConfigFileError('Failed to configure switch s_flipper_left in platform. See error above')>
Traceback (most recent call last):
  File "C:\Users\User\AppData\Local\Programs\Python\Python312\Lib\site-packages\mpf\platforms\fast\fast.py", line 447, in _parse_switch_number
    board = self.io_boards_by_name[board_str]
            ~~~~~~~~~~~~~~~~~~~~~~^^^^^^^^^^^
KeyError: '3208'

During handling of the above exception, another exception occurred:

Traceback (most recent call last):
  File "C:\Users\User\AppData\Local\Programs\Python\Python312\Lib\site-packages\mpf\devices\switch.py", line 149, in _initialize
    self.hw_switch = self.platform.configure_switch(
                     ^^^^^^^^^^^^^^^^^^^^^^^^^^^^^^^
  File "C:\Users\User\AppData\Local\Programs\Python\Python312\Lib\site-packages\mpf\platforms\fast\fast.py", line 505, in configure_switch
    number = self._parse_switch_number(number)
             ^^^^^^^^^^^^^^^^^^^^^^^^^^^^^^^^^
  File "C:\Users\User\AppData\Local\Programs\Python\Python312\Lib\site-packages\mpf\platforms\fast\fast.py", line 449, in _parse_switch_number
    raise AssertionError(f"Board {board_str} does not exist for switch {number}")
AssertionError: Board 3208 does not exist for switch 3208-30

The above exception was the direct cause of the following exception:

Traceback (most recent call last):
  File "C:\Users\User\AppData\Local\Programs\Python\Python312\Lib\site-packages\mpf\core\system_wide_device.py", line 17, in device_added_system_wide
    await self._initialize()
  File "C:\Users\User\AppData\Local\Programs\Python\Python312\Lib\site-packages\mpf\devices\switch.py", line 152, in _initialize
    raise ConfigFileError("Failed to configure switch {} in platform. See error above".format(self.name), 2,
mpf.exceptions.config_file_error.ConfigFileError: Config File Error in switch: Failed to configure switch s_flipper_left in platform. See error above Error Code: CFE-switch-2 (https://missionpinball.org/logs)
2025-03-14 20:29:12,748 : ERROR : asyncio : Task exception was never retrieved
future: <Task finished name='Task-21' coro=<SystemWideDevice.device_added_system_wide() done, defined at C:\Users\User\AppData\Local\Programs\Python\Python312\Lib\site-packages\mpf\core\system_wide_device.py:15> exception=ConfigFileError('Failed to configure switch s_flipper_right in platform. See error above')>
Traceback (most recent call last):
  File "C:\Users\User\AppData\Local\Programs\Python\Python312\Lib\site-packages\mpf\platforms\fast\fast.py", line 433, in _parse_switch_number
    board_str, switch_str = number.split("-")
    ^^^^^^^^^^^^^^^^^^^^^
ValueError: not enough values to unpack (expected 2, got 1)

The above exception was the direct cause of the following exception:

Traceback (most recent call last):
  File "C:\Users\User\AppData\Local\Programs\Python\Python312\Lib\site-packages\mpf\devices\switch.py", line 149, in _initialize
    self.hw_switch = self.platform.configure_switch(
                     ^^^^^^^^^^^^^^^^^^^^^^^^^^^^^^^
  File "C:\Users\User\AppData\Local\Programs\Python\Python312\Lib\site-packages\mpf\platforms\fast\fast.py", line 505, in configure_switch
    number = self._parse_switch_number(number)
             ^^^^^^^^^^^^^^^^^^^^^^^^^^^^^^^^^
  File "C:\Users\User\AppData\Local\Programs\Python\Python312\Lib\site-packages\mpf\platforms\fast\fast.py", line 441, in _parse_switch_number
    raise AssertionError(f"Switch {int(index, 16)} does not exist. Only "
AssertionError: Switch 31 does not exist. Only 0 switches found. Switch number: 31

The above exception was the direct cause of the following exception:

Traceback (most recent call last):
  File "C:\Users\User\AppData\Local\Programs\Python\Python312\Lib\site-packages\mpf\core\system_wide_device.py", line 17, in device_added_system_wide
    await self._initialize()
  File "C:\Users\User\AppData\Local\Programs\Python\Python312\Lib\site-packages\mpf\devices\switch.py", line 152, in _initialize
    raise ConfigFileError("Failed to configure switch {} in platform. See error above".format(self.name), 2,
mpf.exceptions.config_file_error.ConfigFileError: Config File Error in switch: Failed to configure switch s_flipper_right in platform. See error above Error Code: CFE-switch-2 (https://missionpinball.org/logs)
2025-03-14 20:29:12,753 : ERROR : asyncio : Task exception was never retrieved
future: <Task finished name='Task-22' coro=<SystemWideDevice.device_added_system_wide() done, defined at C:\Users\User\AppData\Local\Programs\Python\Python312\Lib\site-packages\mpf\core\system_wide_device.py:15> exception=ConfigFileError('Failed to configure switch s_flipper_left_upper_eos in platform. See error above')>
Traceback (most recent call last):
  File "C:\Users\User\AppData\Local\Programs\Python\Python312\Lib\site-packages\mpf\platforms\fast\fast.py", line 433, in _parse_switch_number
    board_str, switch_str = number.split("-")
    ^^^^^^^^^^^^^^^^^^^^^
ValueError: not enough values to unpack (expected 2, got 1)

The above exception was the direct cause of the following exception:

Traceback (most recent call last):
  File "C:\Users\User\AppData\Local\Programs\Python\Python312\Lib\site-packages\mpf\devices\switch.py", line 149, in _initialize
    self.hw_switch = self.platform.configure_switch(
                     ^^^^^^^^^^^^^^^^^^^^^^^^^^^^^^^
  File "C:\Users\User\AppData\Local\Programs\Python\Python312\Lib\site-packages\mpf\platforms\fast\fast.py", line 505, in configure_switch
    number = self._parse_switch_number(number)
             ^^^^^^^^^^^^^^^^^^^^^^^^^^^^^^^^^
  File "C:\Users\User\AppData\Local\Programs\Python\Python312\Lib\site-packages\mpf\platforms\fast\fast.py", line 441, in _parse_switch_number
    raise AssertionError(f"Switch {int(index, 16)} does not exist. Only "
AssertionError: Switch 20 does not exist. Only 0 switches found. Switch number: 20

The above exception was the direct cause of the following exception:

Traceback (most recent call last):
  File "C:\Users\User\AppData\Local\Programs\Python\Python312\Lib\site-packages\mpf\core\system_wide_device.py", line 17, in device_added_system_wide
    await self._initialize()
  File "C:\Users\User\AppData\Local\Programs\Python\Python312\Lib\site-packages\mpf\devices\switch.py", line 152, in _initialize
    raise ConfigFileError("Failed to configure switch {} in platform. See error above".format(self.name), 2,
mpf.exceptions.config_file_error.ConfigFileError: Config File Error in switch: Failed to configure switch s_flipper_left_upper_eos in platform. See error above Error Code: CFE-switch-2 (https://missionpinball.org/logs)
2025-03-14 20:29:12,755 : ERROR : asyncio : Task exception was never retrieved
future: <Task finished name='Task-23' coro=<SystemWideDevice.device_added_system_wide() done, defined at C:\Users\User\AppData\Local\Programs\Python\Python312\Lib\site-packages\mpf\core\system_wide_device.py:15> exception=ConfigFileError('Failed to configure switch s_flipper_left_lower_eos in platform. See error above')>
Traceback (most recent call last):
  File "C:\Users\User\AppData\Local\Programs\Python\Python312\Lib\site-packages\mpf\platforms\fast\fast.py", line 433, in _parse_switch_number
    board_str, switch_str = number.split("-")
    ^^^^^^^^^^^^^^^^^^^^^
ValueError: not enough values to unpack (expected 2, got 1)

The above exception was the direct cause of the following exception:

Traceback (most recent call last):
  File "C:\Users\User\AppData\Local\Programs\Python\Python312\Lib\site-packages\mpf\devices\switch.py", line 149, in _initialize
    self.hw_switch = self.platform.configure_switch(
                     ^^^^^^^^^^^^^^^^^^^^^^^^^^^^^^^
  File "C:\Users\User\AppData\Local\Programs\Python\Python312\Lib\site-packages\mpf\platforms\fast\fast.py", line 505, in configure_switch
    number = self._parse_switch_number(number)
             ^^^^^^^^^^^^^^^^^^^^^^^^^^^^^^^^^
  File "C:\Users\User\AppData\Local\Programs\Python\Python312\Lib\site-packages\mpf\platforms\fast\fast.py", line 441, in _parse_switch_number
    raise AssertionError(f"Switch {int(index, 16)} does not exist. Only "
AssertionError: Switch 19 does not exist. Only 0 switches found. Switch number: 19

The above exception was the direct cause of the following exception:

Traceback (most recent call last):
  File "C:\Users\User\AppData\Local\Programs\Python\Python312\Lib\site-packages\mpf\core\system_wide_device.py", line 17, in device_added_system_wide
    await self._initialize()
  File "C:\Users\User\AppData\Local\Programs\Python\Python312\Lib\site-packages\mpf\devices\switch.py", line 152, in _initialize
    raise ConfigFileError("Failed to configure switch {} in platform. See error above".format(self.name), 2,
mpf.exceptions.config_file_error.ConfigFileError: Config File Error in switch: Failed to configure switch s_flipper_left_lower_eos in platform. See error above Error Code: CFE-switch-2 (https://missionpinball.org/logs)
2025-03-14 20:29:12,757 : ERROR : asyncio : Task exception was never retrieved
future: <Task finished name='Task-24' coro=<SystemWideDevice.device_added_system_wide() done, defined at C:\Users\User\AppData\Local\Programs\Python\Python312\Lib\site-packages\mpf\core\system_wide_device.py:15> exception=ConfigFileError('Failed to configure switch s_flipper_right_eos in platform. See error above')>
Traceback (most recent call last):
  File "C:\Users\User\AppData\Local\Programs\Python\Python312\Lib\site-packages\mpf\platforms\fast\fast.py", line 433, in _parse_switch_number
    board_str, switch_str = number.split("-")
    ^^^^^^^^^^^^^^^^^^^^^
ValueError: not enough values to unpack (expected 2, got 1)

The above exception was the direct cause of the following exception:

Traceback (most recent call last):
  File "C:\Users\User\AppData\Local\Programs\Python\Python312\Lib\site-packages\mpf\devices\switch.py", line 149, in _initialize
    self.hw_switch = self.platform.configure_switch(
                     ^^^^^^^^^^^^^^^^^^^^^^^^^^^^^^^
  File "C:\Users\User\AppData\Local\Programs\Python\Python312\Lib\site-packages\mpf\platforms\fast\fast.py", line 505, in configure_switch
    number = self._parse_switch_number(number)
             ^^^^^^^^^^^^^^^^^^^^^^^^^^^^^^^^^
  File "C:\Users\User\AppData\Local\Programs\Python\Python312\Lib\site-packages\mpf\platforms\fast\fast.py", line 441, in _parse_switch_number
    raise AssertionError(f"Switch {int(index, 16)} does not exist. Only "
AssertionError: Switch 18 does not exist. Only 0 switches found. Switch number: 18

The above exception was the direct cause of the following exception:

Traceback (most recent call last):
  File "C:\Users\User\AppData\Local\Programs\Python\Python312\Lib\site-packages\mpf\core\system_wide_device.py", line 17, in device_added_system_wide
    await self._initialize()
  File "C:\Users\User\AppData\Local\Programs\Python\Python312\Lib\site-packages\mpf\devices\switch.py", line 152, in _initialize
    raise ConfigFileError("Failed to configure switch {} in platform. See error above".format(self.name), 2,
mpf.exceptions.config_file_error.ConfigFileError: Config File Error in switch: Failed to configure switch s_flipper_right_eos in platform. See error above Error Code: CFE-switch-2 (https://missionpinball.org/logs)
2025-03-14 20:29:12,758 : ERROR : asyncio : Task exception was never retrieved
future: <Task finished name='Task-25' coro=<SystemWideDevice.device_added_system_wide() done, defined at C:\Users\User\AppData\Local\Programs\Python\Python312\Lib\site-packages\mpf\core\system_wide_device.py:15> exception=ConfigFileError('Failed to configure switch s_start in platform. See error above')>
Traceback (most recent call last):
  File "C:\Users\User\AppData\Local\Programs\Python\Python312\Lib\site-packages\mpf\platforms\fast\fast.py", line 433, in _parse_switch_number
    board_str, switch_str = number.split("-")
    ^^^^^^^^^^^^^^^^^^^^^
ValueError: not enough values to unpack (expected 2, got 1)

The above exception was the direct cause of the following exception:

Traceback (most recent call last):
  File "C:\Users\User\AppData\Local\Programs\Python\Python312\Lib\site-packages\mpf\devices\switch.py", line 149, in _initialize
    self.hw_switch = self.platform.configure_switch(
                     ^^^^^^^^^^^^^^^^^^^^^^^^^^^^^^^
  File "C:\Users\User\AppData\Local\Programs\Python\Python312\Lib\site-packages\mpf\platforms\fast\fast.py", line 505, in configure_switch
    number = self._parse_switch_number(number)
             ^^^^^^^^^^^^^^^^^^^^^^^^^^^^^^^^^
  File "C:\Users\User\AppData\Local\Programs\Python\Python312\Lib\site-packages\mpf\platforms\fast\fast.py", line 441, in _parse_switch_number
    raise AssertionError(f"Switch {int(index, 16)} does not exist. Only "
AssertionError: Switch 29 does not exist. Only 0 switches found. Switch number: 29

The above exception was the direct cause of the following exception:

Traceback (most recent call last):
  File "C:\Users\User\AppData\Local\Programs\Python\Python312\Lib\site-packages\mpf\core\system_wide_device.py", line 17, in device_added_system_wide
    await self._initialize()
  File "C:\Users\User\AppData\Local\Programs\Python\Python312\Lib\site-packages\mpf\devices\switch.py", line 152, in _initialize
    raise ConfigFileError("Failed to configure switch {} in platform. See error above".format(self.name), 2,
mpf.exceptions.config_file_error.ConfigFileError: Config File Error in switch: Failed to configure switch s_start in platform. See error above Error Code: CFE-switch-2 (https://missionpinball.org/logs)
2025-03-14 20:29:12,760 : ERROR : asyncio : Task exception was never retrieved
future: <Task finished name='Task-26' coro=<SystemWideDevice.device_added_system_wide() done, defined at C:\Users\User\AppData\Local\Programs\Python\Python312\Lib\site-packages\mpf\core\system_wide_device.py:15> exception=ConfigFileError('Config validation error: Entry ball_device_ejector_pulse:ball_device_ejector_pulse:eject_coil = "c_trough_eject_coil" is not valid. Device "c_trough_eject_coil" not found in "coils:" section in your config.')>
Traceback (most recent call last):
  File "C:\Users\User\AppData\Local\Programs\Python\Python312\Lib\site-packages\mpf\core\system_wide_device.py", line 17, in device_added_system_wide
    await self._initialize()
  File "C:\Users\User\AppData\Local\Programs\Python\Python312\Lib\site-packages\mpf\devices\ball_device\ball_device.py", line 90, in _initialize
    self._configure_targets()
  File "C:\Users\User\AppData\Local\Programs\Python\Python312\Lib\site-packages\mpf\devices\ball_device\ball_device.py", line 386, in _configure_targets
    self.ejector = ejector_class(ejector_config, self, self.machine)
                   ^^^^^^^^^^^^^^^^^^^^^^^^^^^^^^^^^^^^^^^^^^^^^^^^^
  File "C:\Users\User\AppData\Local\Programs\Python\Python312\Lib\site-packages\mpf\devices\ball_device\pulse_coil_ejector.py", line 26, in __init__
    self.config = self.machine.config_validator.validate_config("ball_device_ejector_pulse", self.config)
                  ^^^^^^^^^^^^^^^^^^^^^^^^^^^^^^^^^^^^^^^^^^^^^^^^^^^^^^^^^^^^^^^^^^^^^^^^^^^^^^^^^^^^^^^
  File "C:\Users\User\AppData\Local\Programs\Python\Python312\Lib\site-packages\mpf\core\config_validator.py", line 164, in validate_config
    return self._validate_config(config_spec, source, base_spec=base_spec, add_missing_keys=add_missing_keys,
           ^^^^^^^^^^^^^^^^^^^^^^^^^^^^^^^^^^^^^^^^^^^^^^^^^^^^^^^^^^^^^^^^^^^^^^^^^^^^^^^^^^^^^^^^^^^^^^^^^^
  File "C:\Users\User\AppData\Local\Programs\Python\Python312\Lib\site-packages\mpf\core\config_validator.py", line 204, in _validate_config
    processed_config[k] = self.validate_config_item(
                          ^^^^^^^^^^^^^^^^^^^^^^^^^^
  File "C:\Users\User\AppData\Local\Programs\Python\Python312\Lib\site-packages\mpf\core\config_validator.py", line 243, in validate_config_item
    return self.validate_item(item, validation, validation_failure_info)
           ^^^^^^^^^^^^^^^^^^^^^^^^^^^^^^^^^^^^^^^^^^^^^^^^^^^^^^^^^^^^^
  File "C:\Users\User\AppData\Local\Programs\Python\Python312\Lib\site-packages\mpf\core\config_validator.py", line 699, in validate_item
    return self.validator_list[validator](item, validation_failure_info=validation_failure_info, param=param)
           ^^^^^^^^^^^^^^^^^^^^^^^^^^^^^^^^^^^^^^^^^^^^^^^^^^^^^^^^^^^^^^^^^^^^^^^^^^^^^^^^^^^^^^^^^^^^^^^^^^
  File "C:\Users\User\AppData\Local\Programs\Python\Python312\Lib\site-packages\mpf\core\config_validator.py", line 413, in _validate_type_machine
    raise self.validation_error(item, validation_failure_info,
mpf.exceptions.config_file_error.ConfigFileError: Config File Error in ConfigValidator: Config validation error: Entry ball_device_ejector_pulse:ball_device_ejector_pulse:eject_coil = "c_trough_eject_coil" is not valid. Device "c_trough_eject_coil" not found in "coils:" section in your config. Error Code: CFE-ConfigValidator-6 (https://missionpinball.org/logs)
2025-03-14 20:29:12,764 : INFO : Machine : Starting the main run loop with active modes: []
2025-03-14 20:29:12,764 : WARNING : Machine : Attract mode is not active, game will not be playable. Please check your attract mode configuration.
2025-03-14 20:29:12,765 : INFO : Machine : Shutting down...
2025-03-14 20:29:12,765 : INFO : EventManager : Event: ======'shutdown'====== Args={}
2025-03-14 20:29:13,879 : ERROR : Machine : Runtime Exception
Traceback (most recent call last):
  File "C:\Users\User\AppData\Local\Programs\Python\Python312\Lib\site-packages\mpf\platforms\fast\fast.py", line 447, in _parse_switch_number
    board = self.io_boards_by_name[board_str]
            ~~~~~~~~~~~~~~~~~~~~~~^^^^^^^^^^^
KeyError: '3208'

During handling of the above exception, another exception occurred:

Traceback (most recent call last):
  File "C:\Users\User\AppData\Local\Programs\Python\Python312\Lib\site-packages\mpf\devices\switch.py", line 149, in _initialize
    self.hw_switch = self.platform.configure_switch(
                     ^^^^^^^^^^^^^^^^^^^^^^^^^^^^^^^
  File "C:\Users\User\AppData\Local\Programs\Python\Python312\Lib\site-packages\mpf\platforms\fast\fast.py", line 505, in configure_switch
    number = self._parse_switch_number(number)
             ^^^^^^^^^^^^^^^^^^^^^^^^^^^^^^^^^
  File "C:\Users\User\AppData\Local\Programs\Python\Python312\Lib\site-packages\mpf\platforms\fast\fast.py", line 449, in _parse_switch_number
    raise AssertionError(f"Board {board_str} does not exist for switch {number}")
AssertionError: Board 3208 does not exist for switch 3208-30

The above exception was the direct cause of the following exception:

Traceback (most recent call last):
  File "C:\Users\User\AppData\Local\Programs\Python\Python312\Lib\site-packages\mpf\core\machine.py", line 808, in _run_loop
    raise self._exception['exception']
  File "C:\Users\User\AppData\Local\Programs\Python\Python312\Lib\site-packages\mpf\core\system_wide_device.py", line 17, in device_added_system_wide
    await self._initialize()
  File "C:\Users\User\AppData\Local\Programs\Python\Python312\Lib\site-packages\mpf\devices\switch.py", line 152, in _initialize
    raise ConfigFileError("Failed to configure switch {} in platform. See error above".format(self.name), 2,
mpf.exceptions.config_file_error.ConfigFileError: Config File Error in switch: Failed to configure switch s_flipper_left in platform. See error above Error Code: CFE-switch-2 (https://missionpinball.org/logs)
2025-03-14 20:29:13,882 : INFO : root : MPF run loop ended.
