2025-03-15 00:44:52,050 : INFO : root : Loading config.
2025-03-15 00:44:52,060 : INFO : YamlMultifileConfigLoader : Machine config file #1: config.yaml
2025-03-15 00:44:52,062 : WARNING : ConfigProcessor : Config file in cache changed: C:\Users\User\Desktop\fast_homebrew_godot_v2\fast_homebrew_godot_v2\config\config.yaml
2025-03-15 00:44:52,062 : INFO : ConfigProcessor : Loading config from file C:\Users\User\AppData\Local\Programs\Python\Python312\Lib\site-packages\mpf\mpfconfig.yaml.
2025-03-15 00:44:52,152 : INFO : ConfigProcessor : Loading config: C:\Users\User\AppData\Local\Programs\Python\Python312\Lib\site-packages\mpf\mpfconfig.yaml
2025-03-15 00:44:52,153 : INFO : ConfigProcessor : Loading config from file C:\Users\User\Desktop\fast_homebrew_godot_v2\fast_homebrew_godot_v2\config\config.yaml.
2025-03-15 00:44:52,172 : INFO : ConfigProcessor : Loading config: C:\Users\User\Desktop\fast_homebrew_godot_v2\fast_homebrew_godot_v2\config\config.yaml
2025-03-15 00:44:52,173 : INFO : ConfigProcessor : Loading config: C:\Users\User\Desktop\fast_homebrew_godot_v2\fast_homebrew_godot_v2\config\lights.yaml
2025-03-15 00:44:52,178 : INFO : ConfigProcessor : Loading config: C:\Users\User\Desktop\fast_homebrew_godot_v2\fast_homebrew_godot_v2\config\coils.yaml
2025-03-15 00:44:52,188 : INFO : ConfigProcessor : Loading config: C:\Users\User\Desktop\fast_homebrew_godot_v2\fast_homebrew_godot_v2\config\switches.yaml
2025-03-15 00:44:52,192 : INFO : ConfigProcessor : Loading config: C:\Users\User\Desktop\fast_homebrew_godot_v2\fast_homebrew_godot_v2\config\images.yaml
2025-03-15 00:44:52,194 : INFO : ConfigProcessor : Loading config: C:\Users\User\Desktop\fast_homebrew_godot_v2\fast_homebrew_godot_v2\config\videos.yaml
2025-03-15 00:44:52,200 : INFO : ConfigProcessor : Config file cache created: C:\Users\User\AppData\Local\Temp\5682b9bdeb2b9ad8a31c13560e038609.mpf_cache
2025-03-15 00:44:52,464 : INFO : ConfigProcessor : Loading config from cache: C:\Users\User\AppData\Local\Temp\8422c6572f827355f8aade1949d04025.mpf_cache
2025-03-15 00:44:52,468 : INFO : ConfigProcessor : Loading config from cache: C:\Users\User\AppData\Local\Temp\1c0e7e9816717d8e62c4728dfe372999.mpf_cache
2025-03-15 00:44:52,471 : WARNING : ConfigProcessor : Config file in cache changed: C:\Users\User\Desktop\fast_homebrew_godot_v2\fast_homebrew_godot_v2\modes\base\config\base.yaml
2025-03-15 00:44:52,471 : INFO : ConfigProcessor : Loading config from file C:\Users\User\Desktop\fast_homebrew_godot_v2\fast_homebrew_godot_v2\modes\base\config\base.yaml.
2025-03-15 00:44:52,473 : INFO : ConfigProcessor : Loading config: C:\Users\User\Desktop\fast_homebrew_godot_v2\fast_homebrew_godot_v2\modes\base\config\base.yaml
2025-03-15 00:44:52,473 : INFO : ConfigProcessor : Config file cache created: C:\Users\User\AppData\Local\Temp\e3e8065d662ad307fa9574659e7e4e8e.mpf_cache
2025-03-15 00:44:52,475 : INFO : ConfigProcessor : Loading config from cache: C:\Users\User\AppData\Local\Temp\8422c6572f827355f8aade1949d04025.mpf_cache
2025-03-15 00:44:52,477 : INFO : Machine : Mission Pinball Framework Core Engine v0.80.0.dev6
2025-03-15 00:44:52,477 : INFO : Machine : Command line arguments: {'no_load_cache': False, 'create_config_cache': True, 'bcp': False, 'configfile': ['config.yaml'], 'force_assets_load': False, 'platform_integration_test': False, 'jsonlogging': False, 'logfile': 'logs\\2025-03-15-00-44-52-mpf-BERNIE.log', 'pause': False, 'production': False, 'text_ui': False, 'loglevel': 15, 'consoleloglevel': 20, 'force_platform': None, 'syslog_address': None, 'full_logfile_path': 'C:\\Users\\User\\Desktop\\fast_homebrew_godot_v2\\fast_homebrew_godot_v2\\logs\\2025-03-15-00-44-52-mpf-BERNIE.log'}
2025-03-15 00:44:52,477 : INFO : Machine : MPF path: C:\Users\User\AppData\Local\Programs\Python\Python312\Lib\site-packages\mpf
2025-03-15 00:44:52,477 : INFO : Machine : Machine path: C:\Users\User\Desktop\fast_homebrew_godot_v2\fast_homebrew_godot_v2
2025-03-15 00:44:52,477 : INFO : Machine : Platform: win32
2025-03-15 00:44:52,477 : INFO : Machine : Python executable location: C:\Users\User\AppData\Local\Programs\Python\Python312\python.exe
2025-03-15 00:44:52,477 : INFO : Machine : Python version: 3.12.3 (64-bit)
2025-03-15 00:44:52,487 : INFO : Machine : Initializing MPF...
2025-03-15 00:44:52,772 : INFO : FAST : Auto-detecting ports for the following connections: ['net']
2025-03-15 00:44:52,842 : INFO : FAST : Detected NET on port COM5
2025-03-15 00:44:52,953 : INFO : FAST [NET] : Trying to connect to COM5 at 921600bps
2025-03-15 00:44:52,961 : INFO : FAST [NET] : Connected to COM5 at 921600bps
2025-03-15 00:44:52,968 : INFO : FAST [NET] : Connected to FP-CPU-2000 with firmware v02.26
2025-03-15 00:44:53,002 : INFO : FAST [NET] : Registered I/O Board 0: Model: FP-I/O-3208, Firmware: 01.10, Switches: 32, Drivers: 8
2025-03-15 00:44:53,003 : INFO : EventManager : Event: ======'machine_var_credits_string'====== Args={'value': 'FREE PLAY', 'prev_value': None, 'change': True}
2025-03-15 00:44:53,087 : INFO : EventManager : Event: ======'machine_var_master_volume'====== Args={'value': 0.5, 'prev_value': None, 'change': True}
2025-03-15 00:44:53,087 : INFO : EventManager : Event: ======'machine_var_mpf_version'====== Args={'value': 'Mission Pinball Framework v0.80.0.dev6', 'prev_value': None, 'change': True}
2025-03-15 00:44:53,088 : INFO : EventManager : Event: ======'machine_var_mpf_extended_version'====== Args={'value': 'Mission Pinball Framework v0.80.0.dev6, Config version:6, Show version: 6, BCP version:1.1', 'prev_value': None, 'change': True}
2025-03-15 00:44:53,089 : INFO : EventManager : Event: ======'machine_var_python_version'====== Args={'value': '3.12.3', 'prev_value': None, 'change': True}
2025-03-15 00:44:53,373 : INFO : EventManager : Event: ======'machine_var_platform'====== Args={'value': 'Windows-11-10.0.22631-SP0', 'prev_value': None, 'change': True}
2025-03-15 00:44:53,374 : INFO : EventManager : Event: ======'machine_var_platform_system'====== Args={'value': 'Windows', 'prev_value': None, 'change': True}
2025-03-15 00:44:53,374 : INFO : EventManager : Event: ======'machine_var_platform_release'====== Args={'value': '11', 'prev_value': None, 'change': True}
2025-03-15 00:44:53,374 : INFO : EventManager : Event: ======'machine_var_platform_version'====== Args={'value': '10.0.22631', 'prev_value': None, 'change': True}
2025-03-15 00:44:53,374 : INFO : EventManager : Event: ======'machine_var_platform_machine'====== Args={'value': 'AMD64', 'prev_value': None, 'change': True}
2025-03-15 00:44:53,374 : INFO : EventManager : Event: ======'machine_var_log_file_path'====== Args={'value': 'C:\\Users\\User\\Desktop\\fast_homebrew_godot_v2\\fast_homebrew_godot_v2\\logs\\2025-03-15-00-44-52-mpf-BERNIE.log', 'prev_value': None, 'change': True}
2025-03-15 00:44:53,374 : INFO : EventManager : Event: ======'init_phase_1'====== Args={}
2025-03-15 00:44:53,413 : ERROR : asyncio : Exception in callback EventManager._async_handler_done(<QueuedEvent>)(<Task finishe...our config.')>) at C:\Users\User\AppData\Local\Programs\Python\Python312\Lib\site-packages\mpf\core\events.py:124
handle: <Handle EventManager._async_handler_done(<QueuedEvent>)(<Task finishe...our config.')>) at C:\Users\User\AppData\Local\Programs\Python\Python312\Lib\site-packages\mpf\core\events.py:124>
Traceback (most recent call last):
  File "C:\Users\User\AppData\Local\Programs\Python\Python312\Lib\asyncio\events.py", line 88, in _run
    self._context.run(self._callback, *self._args)
  File "C:\Users\User\AppData\Local\Programs\Python\Python312\Lib\site-packages\mpf\core\events.py", line 127, in _async_handler_done
    future.result()
  File "C:\Users\User\AppData\Local\Programs\Python\Python312\Lib\site-packages\mpf\core\device_manager.py", line 88, in _load_device_modules
    self.load_devices_config(validate=True)
  File "C:\Users\User\AppData\Local\Programs\Python\Python312\Lib\site-packages\mpf\core\device_manager.py", line 146, in load_devices_config
    config[device_name] = collection[device_name].validate_and_parse_config(config[device_name], False)
                          ^^^^^^^^^^^^^^^^^^^^^^^^^^^^^^^^^^^^^^^^^^^^^^^^^^^^^^^^^^^^^^^^^^^^^^^^^^^^^
  File "C:\Users\User\AppData\Local\Programs\Python\Python312\Lib\site-packages\mpf\core\device.py", line 108, in validate_and_parse_config
    self.machine.config_validator.validate_config(
  File "C:\Users\User\AppData\Local\Programs\Python\Python312\Lib\site-packages\mpf\core\config_validator.py", line 164, in validate_config
    return self._validate_config(config_spec, source, base_spec=base_spec, add_missing_keys=add_missing_keys,
           ^^^^^^^^^^^^^^^^^^^^^^^^^^^^^^^^^^^^^^^^^^^^^^^^^^^^^^^^^^^^^^^^^^^^^^^^^^^^^^^^^^^^^^^^^^^^^^^^^^
  File "C:\Users\User\AppData\Local\Programs\Python\Python312\Lib\site-packages\mpf\core\config_validator.py", line 204, in _validate_config
    processed_config[k] = self.validate_config_item(
                          ^^^^^^^^^^^^^^^^^^^^^^^^^^
  File "C:\Users\User\AppData\Local\Programs\Python\Python312\Lib\site-packages\mpf\core\config_validator.py", line 243, in validate_config_item
    return self.validate_item(item, validation, validation_failure_info)
           ^^^^^^^^^^^^^^^^^^^^^^^^^^^^^^^^^^^^^^^^^^^^^^^^^^^^^^^^^^^^^
  File "C:\Users\User\AppData\Local\Programs\Python\Python312\Lib\site-packages\mpf\core\config_validator.py", line 699, in validate_item
    return self.validator_list[validator](item, validation_failure_info=validation_failure_info, param=param)
           ^^^^^^^^^^^^^^^^^^^^^^^^^^^^^^^^^^^^^^^^^^^^^^^^^^^^^^^^^^^^^^^^^^^^^^^^^^^^^^^^^^^^^^^^^^^^^^^^^^
  File "C:\Users\User\AppData\Local\Programs\Python\Python312\Lib\site-packages\mpf\core\config_validator.py", line 413, in _validate_type_machine
    raise self.validation_error(item, validation_failure_info,
mpf.exceptions.config_file_error.ConfigFileError: Config File Error in ConfigValidator: Config validation error: Entry ball_devices:bd_trough:ball_missing_target = "bd_trough" is not valid. Device "bd_trough" not found in "playfields:" section in your config. Error Code: CFE-ConfigValidator-6 (https://missionpinball.org/logs)
2025-03-15 00:44:53,422 : INFO : Machine : Starting the main run loop with active modes: []
2025-03-15 00:44:53,422 : WARNING : Machine : Attract mode is not active, game will not be playable. Please check your attract mode configuration.
2025-03-15 00:44:53,423 : INFO : Machine : Shutting down...
2025-03-15 00:44:53,423 : INFO : EventManager : Event: ======'shutdown'====== Args={}
2025-03-15 00:44:54,537 : ERROR : Machine : Runtime Exception
Traceback (most recent call last):
  File "C:\Users\User\AppData\Local\Programs\Python\Python312\Lib\site-packages\mpf\core\machine.py", line 808, in _run_loop
    raise self._exception['exception']
  File "C:\Users\User\AppData\Local\Programs\Python\Python312\Lib\asyncio\events.py", line 88, in _run
    self._context.run(self._callback, *self._args)
  File "C:\Users\User\AppData\Local\Programs\Python\Python312\Lib\site-packages\mpf\core\events.py", line 127, in _async_handler_done
    future.result()
  File "C:\Users\User\AppData\Local\Programs\Python\Python312\Lib\site-packages\mpf\core\device_manager.py", line 88, in _load_device_modules
    self.load_devices_config(validate=True)
  File "C:\Users\User\AppData\Local\Programs\Python\Python312\Lib\site-packages\mpf\core\device_manager.py", line 146, in load_devices_config
    config[device_name] = collection[device_name].validate_and_parse_config(config[device_name], False)
                          ^^^^^^^^^^^^^^^^^^^^^^^^^^^^^^^^^^^^^^^^^^^^^^^^^^^^^^^^^^^^^^^^^^^^^^^^^^^^^
  File "C:\Users\User\AppData\Local\Programs\Python\Python312\Lib\site-packages\mpf\core\device.py", line 108, in validate_and_parse_config
    self.machine.config_validator.validate_config(
  File "C:\Users\User\AppData\Local\Programs\Python\Python312\Lib\site-packages\mpf\core\config_validator.py", line 164, in validate_config
    return self._validate_config(config_spec, source, base_spec=base_spec, add_missing_keys=add_missing_keys,
           ^^^^^^^^^^^^^^^^^^^^^^^^^^^^^^^^^^^^^^^^^^^^^^^^^^^^^^^^^^^^^^^^^^^^^^^^^^^^^^^^^^^^^^^^^^^^^^^^^^
  File "C:\Users\User\AppData\Local\Programs\Python\Python312\Lib\site-packages\mpf\core\config_validator.py", line 204, in _validate_config
    processed_config[k] = self.validate_config_item(
                          ^^^^^^^^^^^^^^^^^^^^^^^^^^
  File "C:\Users\User\AppData\Local\Programs\Python\Python312\Lib\site-packages\mpf\core\config_validator.py", line 243, in validate_config_item
    return self.validate_item(item, validation, validation_failure_info)
           ^^^^^^^^^^^^^^^^^^^^^^^^^^^^^^^^^^^^^^^^^^^^^^^^^^^^^^^^^^^^^
  File "C:\Users\User\AppData\Local\Programs\Python\Python312\Lib\site-packages\mpf\core\config_validator.py", line 699, in validate_item
    return self.validator_list[validator](item, validation_failure_info=validation_failure_info, param=param)
           ^^^^^^^^^^^^^^^^^^^^^^^^^^^^^^^^^^^^^^^^^^^^^^^^^^^^^^^^^^^^^^^^^^^^^^^^^^^^^^^^^^^^^^^^^^^^^^^^^^
  File "C:\Users\User\AppData\Local\Programs\Python\Python312\Lib\site-packages\mpf\core\config_validator.py", line 413, in _validate_type_machine
    raise self.validation_error(item, validation_failure_info,
mpf.exceptions.config_file_error.ConfigFileError: Config File Error in ConfigValidator: Config validation error: Entry ball_devices:bd_trough:ball_missing_target = "bd_trough" is not valid. Device "bd_trough" not found in "playfields:" section in your config. Error Code: CFE-ConfigValidator-6 (https://missionpinball.org/logs)
2025-03-15 00:44:54,541 : INFO : root : MPF run loop ended.
